Workbook

Sheet AIML_cost
A1: A. Customisation and Deployment of Solution - One off Cost
A2: AI chatbot - AI/ML Solution Development
A3: One-Time Framework Cost (Reusable KIAA Components)
A4: Description | D4: total_cost
A5: KIAA Converse Framework – Conversational AI with RAG-based responses, hybrid flows, and contextual retrieval | D5: 10000
A6: Description | B6: hrs | C6: Cost per hour | D6: total_cost
A7: Planning - Customising AIML Framework for current requirement | B7: =SUM(B8:B16) -> 128 | D7: =SUM(D8:D16) -> 3200
A8: Data Source Audit & Selection – mapping vehicle listings, FAQs, policies, and CRM content. | B8: 16 | C8: =lookup!$B$2 -> 25 | D8: =B8*$C8 -> 400
A9: Schema Design & Entity Mapping – defining tagging schema for car-related attributes (make, model, pricing, policies) | B9: 16 | C9: =lookup!$B$2 -> 25 | D9: =B9*$C9 -> 400
A10: Knowledge Structuring Plan – defining how data will be represented (vector store + metadata graph). | B10: 8 | C10: =lookup!$B$2 -> 25 | D10: =B10*$C10 -> 200
A11: RAG Architecture Design – defining retriever ranker setup, context window strategy, and grounding source hierarchy. | B11: 24 | C11: =lookup!$B$2 -> 25 | D11: =B11*$C11 -> 600
A12: Prompt Design & Response Strategy – defining how the LLM responds, clarifies, or escalates | B12: 16 | C12: =lookup!$B$2 -> 25 | D12: =B12*$C12 -> 400
A13: Memory & Personalization Writebacks - Plan structure for storing user memory (preferences, chat summary). | B13: 8 | C13: =lookup!$B$2 -> 25 | D13: =B13*$C13 -> 200
A14: Evaluation Metric Definition – defining key metrics: retrieval precision, latency, factual accuracy. | B14: 8 | C14: =lookup!$B$2 -> 25 | D14: =B14*$C14 -> 200
A15: Output & Integration Schema Design – define canonical AI_Response schema, downstream mappings (CRM, UI, analytics), structured outputs (text, cards, quick replies), and escalation payloads. | B15: 24 | C15: =lookup!$B$2 -> 25 | D15: =B15*$C15 -> 600
A16: Plan for data refresh & governance | B16: 8 | C16: =lookup!$B$2 -> 25 | D16: =B16*$C16 -> 200
A17: Development - AIML Framework | B17: =SUM(B18:B27) -> 152 | D17: =SUM(D18:D27) -> 4560
A18: Knowledge Base Connector Setup: Integrate website FAQs, documents, and spreadsheets with the RAG indexing pipeline. | B18: 32 | C18: =lookup!$C$2 -> 30 | D18: =B18*$C18 -> 960
A19: Data Curation & Pre-processing – cleaning extracted website and policy data, removing redundancy. | B19: 16 | C19: =lookup!$C$2 -> 30 | D19: =B19*$C19 -> 480
A20: Semantic Tagging Model Adaptation – applying and testing tagging schema for automotive context. | B20: 8 | C20: =lookup!$C$2 -> 30 | D20: =B20*$C20 -> 240
A21: Knowledge Graph Construction – linking structured (CRM, inventory) and unstructured (web) sources. | B21: 24 | C21: =lookup!$C$2 -> 30 | D21: =B21*$C21 -> 720
A22: Vector Store & Embedding Indexing – setting up hybrid store for semantic + keyword retrieval. | B22: 16 | C22: =lookup!$C$2 -> 30 | D22: =B22*$C22 -> 480
A23: RAG Pipeline Implementation – orchestrating retriever, ranker, and response generator. | B23: 16 | C23: =lookup!$C$2 -> 30 | D23: =B23*$C23 -> 480
A24: Agentic Workflow Implementation – implementing decision logic (answer / clarify / escalate). | B24: 16 | C24: =lookup!$C$2 -> 30 | D24: =B24*$C24 -> 480
A25: Confidence & Guardrail Routing - Define thresholds and escalation rules based on confidence, intent, or sentiment. | B25: 8 | C25: =lookup!$C$2 -> 30 | D25: =B25*$C25 -> 240
A26: Testing & Validation – model evaluation, hallucination control, and accuracy tuning. | B26: 8 | C26: =lookup!$C$2 -> 30 | D26: =B26*$C26 -> 240
A27: Continuous Learning Hooks – setting up retraining triggers and feedback loop capture | B27: 8 | C27: =lookup!$C$2 -> 30 | D27: =B27*$C27 -> 240
A28: Integration Effort | B28: =SUM(B29:B31) -> 0 | D28: =SUM(D29:D31) -> 0
A29: Integration with Zoho CRM | B29: 0 | C29: =[1]lookup!$C$2 -> 30 | D29: =B29*$C29 -> 0
A30: Feedback loop integration | B30: 0 | C30: =[1]lookup!$C$2 -> 30 | D30: =B30*$C30 -> 0
A31: Integration testing | B31: 0 | C31: =[1]lookup!$C$2 -> 30 | D31: =B31*$C31 -> 0
A32: Documentation - AIML Framework | B32: =SUM(B33:B35) -> 0 | D32: =SUM(D33:D35) -> 0
A33: Code Standardization | B33: 0 | C33: =[1]lookup!$B$2 -> 25 | D33: =B33*$C33 -> 0
A34: Code Documentation | B34: 0 | C34: =[1]lookup!$B$2 -> 25 | D34: =B34*$C34 -> 0
A35: Documentation - user manual | B35: 0 | C35: =[1]lookup!$B$2 -> 25 | D35: =B35*$C35 -> 0
A36: Testing - AIML Framework | B36: =SUM(B37:B38) -> 62 | D36: =SUM(D37:D38) -> 1550 | G36: AI/ML | I36: API
A37: Unit testing | B37: =ROUNDUP(0.2*B17,0) -> 31 | C37: =[1]lookup!$D$2 -> 25 | D37: =B37*$C37 -> 775 | G37: 350 | I37: 328
A38: Data quality | B38: =ROUNDUP(0.2*B17,0) -> 31 | C38: =[1]lookup!$D$2 -> 25 | D38: =B38*$C38 -> 775 | G38: =G37/140 -> 2.5 | I38: =I37/140 -> 2.3428571
A39: Total Production Man Hours | B39: =SUM(B7,B17,B28,B32,B36) -> 342 | G39: =G38/2 -> 1.25 | I39: =I38/2 -> 1.1714286
A40: Total Cost | D40: =SUM(D7,D17,D28,D32,D36) -> 9310 | G40: Week 1 - Week 5
...

Sheet DataHarvesting_CostEstimation
A1: Robust Solution Development for Automotive data scraping
A3: I. Design, Development and Deployment of Solution - One off Cost
A4: S.No | B4: Project Task / Activity Description | C4: Cost per hour | D4: Effort in Hours | E4: Total Cost
A6: 1 | B6: Planning, Design and System Set up | C6: =J8 -> 22 | D6: 4 | E6: =C6*D6 -> 88
A7: 1.2 | B7: Solution Approach (System Architecture and Database Design) | D7: 2 | I7: plan | J7: dev | K7: testing | L7: pm
A8: 1.3 | B8: Infrastructure Setup | D8: 2 | H8: Labor cost | I8: 22 | J8: 22 | K8: 22 | L8: 22
A10: 2 | B10: Scraper Development/Configuration | C10: =J8 -> 22 | D10: =D11 -> 14 | E10: =C10*D10 -> 308 | G10: 88 | H10: =G10*110% -> 96.8
A11: 2.1 | B11: Scraper Configuration(The effort includes collection of all details from the home page and the FAQ details) | D11: 14 | G11: 352 | H11: =G11*110% -> 387.2
A12: 3 | B12: Data Transformation, Logging, Alerts, Reports and Delivery | C12: =J8 -> 22 | D12: 2 | E12: =C12*D12 -> 44 | G12: 132 | H12: =G12*110% -> 145.2
A13: 3.1 | B13: Download and Upload processed files(Raw responses will be stored) | D13: 1 | H13: =SUM(H10:H12) -> 629.2
A14: 3.4 | B14: Logging | D14: 1
A15: 4 | B15: Data Quality & Validation | C15: =J8 -> 22 | D15: 2 | E15: =C15*D15 -> 44
A16: 4.1 | B16: Automated Checks - Data Validation
A17: 5 | B17: UAT Issue Fixes | C17: =J8 -> 22 | D17: 2 | E17: =C17*D17 -> 44
A18: 6 | B18: Integration and Deployment | C18: =J8 -> 22 | D18: 2 | E18: =C18*D18 -> 44
A19: 7 | B19: Documentation | C19: =J8 -> 22 | D19: 0 | E19: =C19*D19 -> 0
A20: 8 | B20: Project Management | C20: =J8 -> 22 | D20: 0 | E20: =C20*D20 -> 0
A21: 8.1 | B21: Project Management Charges(PM and BAs)
A22: 9 | B22: Infrastructure Charges During Set Up | E22: =E40 -> 250
A23: 9.1 | B23: To be paid on actuals
B24: Total Estimated Hours | C24: =J8 -> 22 | D24: =SUM(D6,D10,D12,D15,D17,D18,D19,D20) -> 26 | E24: =SUM(E6,E10,E12,E15,E17,E18,E19,E20,E22) -> 822
B25: Buffer for Contingencies(10%) | C25: =J8 -> 22 | D25: =D24*0.1 -> 2.6 | E25: =C25*D25 -> 57.2
B26: Total Set Up Costs | D26: =SUM(D24+D25) -> 28.6 | E26: =SUM(E24+E25) -> 879.2 | F26: =E26-250 -> 629.2
A29: * Note :Costs will be impacted if scraper schedule changes to daily/ monthly or any other custom schedule
A31: II. BAU - Ongoing Recurring Cost (Scrpaers Run Daily *) - Monthly Charges
A32: II.1 | B32: Support and Maintenance Resources | D32: FTE(Quantity) | E32: Cost
A33: II.1.a | B33: Support and Maintenance (Tech Resources) | D33: 0.1 | E33: =D33*3000 -> 300
A34: I.2 | B34: Infrastructire Charges During BAU | F34: Azure infra costs
A35: II.2.a | B35: Proxies for Scraping(3 Ips) | D35: Approximately | E35: 20 | F35: 20
A36: II.2.b | B36: Virtual Machine(Ubuntu) | C36: 1 B4as v2 (4 vCPUs, 16 GB RAM) x 730 Hours (Pay as you go), Linux, (Pay as you go); 1 managed disk – E6; Inter Region transfer type, 5 GB outbound data transfer from UK South to East Asia | D36: Approximately | E36: 50 | F36: 97.71
A37: II.2.c | B37: MySQL | C37: Flexible Server Deployment, General Purpose Tier, 1 D4DS v4 (4 vCores) x 730 Hours, 300 GB Storage with LRS redundancy, 100 million Paid IO, 0 GB Additional Backup storage with LRS, without High availability | D37: Approximately | E37: 150 | F37: 271.69
A38: II.2.d | B38: Document Storage | D38: Approximately | E38: 20 | F38: 20
A39: II.2.e | B39: Back-up | D39: Approximately | E39: 10 | F39: 10
B40: Total Monthly Cost | E40: =SUM(E35:E39) -> 250 | F40: =SUM(F35:F39) -> 419.4
A42: Notes
A43: 1 | B43: Infrastructure costs may vary depending on changes to the scraper execution frequency, such as transitioning to daily, monthly, or other custom schedules.
A44: 2 | B44: This effort estimation is applicable solely to the data sources outlined in this proposal. Integration of any new sources in the future will require separate complexity assessment and effort estimation.
A45: 3 | B45: The proposed infrastructure is capable of supporting the concurrent operation of 5 to 10 scraper instances.
A46: 4 | B46: Any website changes will be billed at £25 per hour. If a site changes, we will first analyse the impact and then provide an estimate of the effort required to update our scraper configuration accordingly.

Sheet AIML_COST_SUMMARY
A1: Description | B1: Hours | C1: Cost
A2: KIAA Converse Framework – Conversational AI with RAG-based responses, hybrid flows, and contextual retrieval | C2: =AIML_cost!D5 -> 10000
A3: Planning - Customising AIML Framework for current requirement | B3: =VLOOKUP($A3,AIML_cost!$A:$D,2,0) -> 128 | C3: =VLOOKUP($A3,AIML_cost!$A:$D,4,0) -> 3200
A4: Development - AIML Framework | B4: =VLOOKUP($A4,AIML_cost!$A:$D,2,0) -> 152 | C4: =VLOOKUP($A4,AIML_cost!$A:$D,4,0) -> 4560
A5: Integration Effort | B5: =VLOOKUP($A5,AIML_cost!$A:$D,2,0) -> 0 | C5: =VLOOKUP($A5,AIML_cost!$A:$D,4,0) -> 0
A6: Documentation - AIML Framework | B6: =VLOOKUP($A6,AIML_cost!$A:$D,2,0) -> 0 | C6: =VLOOKUP($A6,AIML_cost!$A:$D,4,0) -> 0
A7: Testing - AIML Framework | B7: =VLOOKUP($A7,AIML_cost!$A:$D,2,0) -> 62 | C7: =VLOOKUP($A7,AIML_cost!$A:$D,4,0) -> 1550
A8: PM & Contingency | B8: =VLOOKUP($A8,AIML_cost!$A:$D,2,0) -> 0 | C8: =VLOOKUP($A8,AIML_cost!$A:$D,4,0) -> 2793
A9: Total Infra cost for initial phase | B9: =VLOOKUP($A9,AIML_cost!$A:$D,2,0) -> 0 | C9: =VLOOKUP($A9,AIML_cost!$A:$D,4,0) -> 315
A10: Total One-time development Cost - AIML | C10: =SUM(C2:C9) -> 22418
A11: BAU - Ongoing Recurring Cost - monthly | C11: =VLOOKUP($A11,AIML_cost!$A:$D,4,0) -> 1055

Sheet API Integration
A1: # | B1: Activity | C1: Description | D1: Est. hours | E1: Hourly Cost | F1: Total
A2: 1 | B2: Environments & foundations | C2: RGs, Bot reg, App Insights, Key Vault, baseline IaC | D2: 16 | E2: 30 | F2: =D2*E2 -> 480
A3: 2 | B3: Zoho OAuth2 setup | C3: Zoho app, consent, refresh-token flow, Key Vault wiring | D3: 16 | E3: 30 | F3: =D3*E3 -> 480
A4: 3 | B4: APIM façade | C4: Products, policies (retry/jitter, 429s), PII masking, logging | D4: 16 | E4: 30 | F4: =D4*E4 -> 480
A5: 4 | B5: Contact upsert | C5: Email/phone dedupe, create/update, validation, tests | D5: 24 | E5: 30 | F5: =D5*E5 -> 720
A6: 5 | B6: Deal create/update | C6: Link to Contact, default pipeline/stage, idempotency | D6: 24 | E6: 30 | F6: =D6*E6 -> 720
A7: 6 | B7: Context fetch middleware | C7: Cosmos profile cache, Zoho lookups (status, last deal), language pref | D7: 32 | E7: 30 | F7: =D7*E7 -> 960
A8: 7 | B8: Open tickets (Zoho Desk) | C8: Ticket lookup, mapping, resilient fallbacks | D8: 16 | E8: 30 | F8: =D8*E8 -> 480
A9: 8 | B9: Chat history | C9: Cosmos schema + write/read path for agent handoff | D9: 16 | E9: 30 | F9: =D9*E9 -> 480
A10: 9 | B10: Webhooks | C10: Zoho CRM/Desk → Event Grid → Functions, cache refresh | D10: 16 | E10: 30 | F10: =D10*E10 -> 480
A11: 10 | B11: Analytics & KPIs | C11: Event schema, KQL queries, Power BI dashboard, optional nightly CRM roll-up | D11: 32 | E11: 30 | F11: =D11*E11 -> 960
A12: 11 | B12: Security & compliance | C12: RBAC, secrets, private endpoints (where used), audit | D12: 8 | E12: 30 | F12: =D12*E12 -> 240
A13: 12 | B13: CI/CD | C13: Pipelines for Functions & infra (Bicep/Terraform), slot swaps | D13: 16 | E13: 30 | F13: =D13*E13 -> 480
... A15: 14 | B15: UAT & handover | C15: UAT support, runbook, admin docs/training | D15: 24 | E15: 30 | F15: =D15*E15 -> 720
B16: Contingency (≈20% of eng.) | C16: Scope wiggle (fields, reports, Desk access) | D16: =0.2*SUM(D2:D15) -> 57.6 | E16: 30 | F16: =D16*E16 -> 1728
B17: Total | D17: =SUM(D2:D16) -> 345.6 | E17: 30 | F17: =SUM(F2:F16) -> 10368
F19: Infra
F20: Resource | G20: Purpose | H20: Suggested SKU / Meter | I20: Unit price (USD) | J20: Usage assumption | K20: Est. monthly | L20: Est. monthly in GBP
F21: Azure API Management | G21: Secure Zoho calls, policies, observability | H21: Basic v2 (prod) | I21: ~$150/mo | J21: 1 unit | K21: 150 | L21: =K21*0.76 -> 114
H22: Developer (non-prod) | I22: ~$48/mo | J22: 1 unit (dev/test only) | K22: 48 | L22: =K22*0.76 -> 36.48
F23: Azure Functions (Consumption) | G23: OAuth/token svc, upserts, context, webhooks | H23: Execs: first 1M free; 400k GB-s free | I23: $0.20 / 1M execs; ~$0.000016/GB-s | J23: ~17.4k execs, ~4.3k GB-s → all within free grants | K23: 0 | L23: =K23*0.76 -> 0
F24: Azure Event Grid | G24: Receive Zoho webhooks → Functions | H24: Basic tier | I24: $0.60 / 1M ops; first 100k free | J24: ~5–20k events/mo | K24: 0 | L24: =K24*0.76 -> 0
F25: Azure Key Vault (Standard) | G25: Secrets: Zoho client/secret/refresh token | H25: $0.03 / 10k ops | I25: ~20k ops/mo | J25: $0.06 | K25: 0.06 | L25: =K25*0.76 -> 0.0456
F26: Azure Cosmos DB (Serverless) | G26: Profile cache + chat snippets | H26: $0.25 / 1M RU + storage | I26: ~0.1–1M RU + 1–5 GB | J26: $0.03–$1.50 | K26: 1.5 | L26: =K26*0.76 -> 1.14
F27: Azure Monitor / App Insights | G27: Telemetry + KPI events | H27: Data ingestion | I27: ~$2–$3 per GB (region-dependent) | J27: ~0.5–2 GB/mo typical for this load | K27: 10 | L27: =K27*0.76 -> 7.6
F28: Azure Storage (optional) | G28: Blob for exports/backups | H28: Hot LRS | I28: ~$0.018/GB-mo | J28: 5 GB | K28: 0.1 | L28: =K28*0.76 -> 0.076
F29: Azure Bot Service | G29: Channel hookup | H29: Standard channels free | I29: — | J29: — | K29: 0 | L29: =K29*0.76 -> 0
K30: =SUM(K21:K29) -> 209.66 | L30: =SUM(L21:L29) -> 159.3416
K31: USD

Sheet For Proposal Costing Table
A1: Description ​ | B1: Cost ​ | D1: BAU Costing
A2: Solution Design, System Set and Configuration for Data Harvesting | B2: =DataHarvesting_CostEstimation!F26 -> 629.2 | D2: Tech Support Resource for Scraping | E2: 0.1 | F2: =E2*3000 -> 300 | J2: S.No​ | K2: Description​ | L2: Estimated Cost​
A3: =AIML_COST_SUMMARY!A2 -> KIAA Converse Framework – Conversational AI with RAG-based responses, hybrid flows, and contextual retrieval | B3: =AIML_COST_SUMMARY!C2 -> 10000 | D3: Tech Support Resource for AI | E3: 0.25 | F3: =E3*3000 -> 750 | J3: I​ | K3: Proxies for Scraping(3 Ips)​ | L3: £20​
A4: =AIML_COST_SUMMARY!A3 -> Planning - Customising AIML Framework for current requirement | B4: =AIML_COST_SUMMARY!C3 -> 3200 | D4: Infrastructure Cost | F4: 724 | J4: II​ | K4: Virtual Machine(Ubuntu) for Scraping​ | L4: £50​
A5: =AIML_COST_SUMMARY!A4 -> Development - AIML Framework | B5: =AIML_COST_SUMMARY!C4 -> 4560 | D5: Monthly Total | F5: =SUM(F2:F4) -> 1774 | J5: III​ | K5: MySQL​ | L5: £150​
A6: =AIML_COST_SUMMARY!A5 -> Integration Effort | B6: =AIML_COST_SUMMARY!C5 -> 0 | J6: IV​ | K6: Document Storage​ | L6: £20​
A7: =AIML_COST_SUMMARY!A6 -> Documentation - AIML Framework | B7: =AIML_COST_SUMMARY!C6 -> 0 | J7: V​ | K7: Back-up​ | L7: £10​
A8: =AIML_COST_SUMMARY!A7 -> Testing - AIML Framework | B8: =AIML_COST_SUMMARY!C7 -> 1550 | J8: VI​ | K8: Virtual Machine(Ubuntu) for AI​ | L8: £180​
A9: =AIML_COST_SUMMARY!A8 -> PM & Contingency | B9: =AIML_COST_SUMMARY!C8 -> 2793 | J9: VII​ | K9: Overall token costs per month​ | L9: £135​
A10: API Integration | B10: ='API Integration'!F17 -> 10368 | J10: Total Monthly Cost​ | L10: £565 ​
A11: Total Solution Set Up / Configuration Costs​ | B11: =SUM(B2:B10) -> 33100.2 | K11: Azure API Management | L11: 114
A12: Total Infra Costs ​ | B12: =SUM(AIML_COST_SUMMARY!C9+DataHarvesting_CostEstimation!E22+'API Integration'!L30) -> 724.3416 | L12: 36.48
A13: ​ | B13: ​ | K13: Azure Functions (Consumption) | L13: 0
A14: Total Cost of Solution Customisation / Configuration ​ | B14: =SUM(B11,B12) -> 33824.542 | K14: Azure Event Grid | L14: 0
K15: Azure Key Vault (Standard) | L15: 0.0456
A16: Infrastructure + token costs ( * Approximate one time Set up cost for development but will be charged on actuals) | K16: Azure Cosmos DB (Serverless) | L16: 1.14
A17: Total Infra cost for initial phase | D17: =SUM(D18,D22) -> 315 | E17: Notes | K17: Azure Monitor / App Insights | L17: 7.6
A18: Virtual Machine(Ubuntu) - AMD EPYC 9554 - CPU-8x-32GB | D18: 180 | E18: 1 | F18: Infrastructure costs may vary depending on changes to the scraper execution frequency, such as transitioning to daily, monthly, or other custom schedules. | K18: Azure Storage (optional) | L18: 0.076
A19: Open AI - token cost | E19: 2 | F19: This effort estimation is applicable solely to the data sources outlined in this proposal. Integration of any new sources in the future will require separate complexity assessment and effort estimation. | K19: Azure Bot Service | L19: 0
A20: Average Token Cost per Conversation | D20: 0.06 | E20: 3 | F20: The proposed infrastructure is capable of supporting the concurrent operation of 5 to 10 scraper instances. | K20: Integration Infra | L20: =SUM(L11:L19) -> 159.3416
A21: Conversations per day 90 * 25 days | D21: =90*25 -> 2250 | E21: 4 | F21: Any website changes will be billed at £25 per hour. If a site changes, we will first analyse the impact and then provide an estimate of the effort required to update our scraper configuration accordingly. | K21: Total Infra | L21: =565+159 -> 724
A22: Overall token cost for PoC | D22: =D21*D20 -> 135
A24: BAU - Ongoing Recurring Cost
A25: Average Token cost per conversation (based on current pricing of openAI and the samples provided) - Alternate between usage of 4o, o3 and o4-mini based on type of response | D25: 0.06
A26: Conversations per day 90 * 25 days | D26: =90*25 -> 2250
A27: Overall token costs per month | D27: =D26*D25 -> 135
A28: Support and Maintenance (Tech Resources) - 0.25 FTE ML engineer per month | D28: =3000*0.25 -> 750
A29: Virtual Machine(Ubuntu) - AMD EPYC 9554 - CPU-8x-32GB | D29: 170
A30: Solution running cost
A31: BAU - Ongoing Recurring Cost - monthly | D31: =SUM(D29,D28,D27) -> 1055

Sheet from_BCL_estimate
B1: Proposal1
A2: 1. One-Time Costs (Setup & Customization)
A3: These costs cover the initial setup, AI model customization, integration, and testing.
A4: Component | B4: Cost (£)
A5: KIAA AI Platform Setup (Smart Recommender & AI Chatbot Framework) | B5: £65,000 | C5: =AIML_COST_SUMMARY!C10 -> 22418
A6: Customization (Recommender & Chatbot Features) | B6: £24,300
A7: Integration & Testing (Azure AI Bot Service, multi-channel deployment, security & compliance testing) | B7: £13,680
A8: Data Curation (One-time costs for extracting static website content, dynamic content updates) | B8: £4,200
A9: Add-ons (Optional Multi-Language Support, Custom Integrations) | B9: £7,200
A10: Total One-Time Costs | B10: £1,14,380
A11: 2. Ongoing Monthly Costs
A12: These include hosting, cloud infrastructure, AI model consumption, and maintenance support.
A13: Component | B13: Cost (£)
A14: Hosting & Compute (Azure VM, OpenAI GPT-4o Mini, Azure Translator API) | B14: £858
A15: Support & Maintenance (ML Engineers, Technical Resources) | B15: £3,000
A16: Total Monthly Ongoing Costs | B16: £3,858
A17: 3. Pay-As-You-Go Message-Based Usage Costs
A18: The chatbot follows a tiered message pricing model, where the cost depends on message volume and hosting type.
A19: Hosting Type | B19: First 100k Messages (£/month)
A20: Standard Hosting (Shared Environment) | B20: £566
A21: Independent Hosting (Dedicated Environment) | B21: £1,506
A22: 4. Total Cost Estimates
A23: Below are the estimated costs based on setup, ongoing operations, and message-based usage.
A24: Cost Category | B24: Total Cost (£)
A25: Total One-Time Costs | B25: £1,14,380
A26: Total Monthly Ongoing Costs | B26: £3,858
A27: Total Monthly Cost (Standard Hosting, 100k messages) | B27: £4,424
A28: Total Monthly Cost (Independent Hosting, 100k messages) | B28: £5,364

Sheet lookup
B1: plan | C1: dev | D1: testing | H1: Role | I1: Effort%
A2: Labor cost | B2: 25 | C2: 30 | D2: 25 | H2: Solution Architect | I2: 0.1
A3: UI labor cost | C3: 22 | H3: PM | I3: 0.05
H4: BA | I4: 0.05
H5: Contingency | I5: 0.1
B6: plan | C6: dev
A7: Solution Architect Effort | B7: 0 | C7: 0
A8: PM Effort | B8: 0 | C8: 0
A9: Dev Unit Testing | B9: 0.2 | C9: 0.2
A10: QA Testing | B10: 0.25 | C10: 0.25
A11: Integration Testing | B11: 0.2 | C11: 0.2
A13: BA Effort | B13: 0 | C13: 0
A17: Scraping Labor cost
B18: plan | C18: dev | D18: testing
A19: Labor cost | B19: 22 | C19: 22 | D19: 22
