Workbook
Name AMENITIES: #REF!
Name BAKERY: #REF!
Name CASH: #REF!
Name CHICKEN: #REF!
Name DELI: #REF!
Name FISH: #REF!
Name FRONTEND: #REF!
Name Fruit: #REF!
Name GENERAL: #REF!
Name LIQUOR: #REF!
Name MANAGER: #REF!
Name MEAT: #REF!
Name RESTROOMS: #REF!
Name STAFFROOM: #REF!
Name STAFFROOM___AMENITIES: #REF!
Name STAFFROOM___AMENITIES: #REF!
Name STAFFROOM___AMENITIES: #REF!
Name STAFFROOM___AMENITIES: #REF!
Name STAFFROOM___AMENITIES: #REF!
Name STAFFROOM___AMENITIES: #REF!
Name STAFFROOM___AMENITIES: #REF!
Name STAFFROOM___AMENITIES: #REF!
Name STAFFROOM___AMENITIES: #REF!
Name STAFFROOM___AMENITIES: #REF!
Name STAFFROOM___AMENITIES: #REF!
Name STAFFROOM___AMENITIES: 'Team Room and Amenities'!$A$18
Name STAFFROOM___AMENITIES: #REF!
Name STAFFROOM___AMENITIES: #REF!
Name STOCKROOM: #REF!
Name TRADING: #REF!
Name TRAINING: #REF!

Sheet Bakery
A1: Store Name: Woolloongabba | B1: RENEWAL & NEW STORE STORE - DAY WORKS AND NIGHT WORKS
A2: Store Number: 2865 | B2: FITOUT PERIOD AS PER PM'S & BUILDERS PROGRAM | D2: V8
A3: Plan Number Tendered On: Control Plan K 10/11/21 | B3: START TBA COMPLETION DATE TBA - SUBJECT TO CHANGE | D3: Updated
A4: Date SOW Completed: 08/02/2022 | B4: Shift P to enter a Tick | D4: 44082
A5: BAKERY
A6: Equipment | B6: Fixing method | C6: Tick | D6: Work Done By
A7: Coolroom Racking / Freezer Room / Dry Store Racking | B7: Relocate if required from existing coldrooms to new location as per Control Plan Assemble new if required as per the assembly instructions and locate as per Control Plan Adjust feet to ensure racking is level Install 'SWL' stickers into clip onto each bay Dismantle and dispose of existing racking where directed | C7: Y | D7: Shopfitter
A8: Paper Towel Dispenser (Tork) | B8: Installation location as per Control Plan Fixed to the wall using plugs and screws and sealed to the wall using silicon Fixed to the wall at a height of 940mm FFL (bottom) Note - store specific level may need to be confirmed by EPM pending any store specific obstructions. | C8: Y | D8: Shopfitter
A9: Cleaning Cloth Dispenser | B9: Installation location as per Control Plan Fixed to the wall using plugs and screws and sealed to the wall using silicon Fixed to the wall at a height no higher than the paper towel dispenser Do not install under the draining rack / storage rack above sink | C9: Y | D9: Shopfitter
A10: Wall Bracket for Mop Rack and Brush Rack (Cleaning products) (White) | B10: Installation location as per Control Plan Fixed to the wall using plugs and screws and sealed to the wall using silicon Fixed to the wall at a height of 1500mm above floor level for both units | C10: Y | D10: Shopfitter
A11: Hose Reel Holder | B11: Installation location as per Control Plan | C11: Y | D11: Shopfitter/Builder
A12: Knife Holder | B12: Installation location as per Control Plan Fixed using plugs and screws Screws are not to be too tight/flush due to the knife holder design of being removable | C12: Y | D12: Shopfitter
A13: Insectocutor (Vectothor Osprey LED) | B13: "Install as per Control Plan Wall mount a min of 1.8m from the base of the unit to floor level Avoid heat oil and sharp edges Use hardware provided in the kit for installation Excess power cord to be coiled neartly to required length. (Do not cut/trim power cord as this will void warranty) Install to the left of the Power supply" | C13: Y | D13: Shopfitter
A14: Hairnet Dispenser | B14: Install as per plan or EPM location | C14: Y | D14: Shopfitter
A15: Low Height, Naked Bread and Full Height Units | B15: Assemble as per the assembly guidelines and locate as per control plan Dismantle and dispose of existing fixtures where directed. (Renewals only) Relocate existing as per control plan | C15: Y | D15: Shopfitter
A16: Bread Tables/Train | B16: Assemble as per the assembly guidelines and locate as per control plan Dismantle and dispose of existing fixtures where directed. (Renewals only) Relocate existing as per control plan | C16: Y | D16: Shopfitter
A17: Naked Perimeter Wall Unit | B17: Assemble as per the assembly guidelines and locate as per control plan | C17: Y | D17: Shopfitter
... A21: Prepare Accessory Equipment for Checking Off in Bakery | B21: Position equipment in department for checking as per control plan | C21: Y | D21: Shopfitter
A22: Can Opener | B22: Locate as per control plan Fixed to bench using screws and siliconed off | D22: Shopfitter
A23: Condiment Rack | B23: Fixed to the wall using plugs and screws Location to be advised by EPM after advice from renewal fresh food coach | C23: Y | D23: Shopfitter
A24: Cooling Trolleys/Racks | B24: Locate as control plan | C24: Y | D24: Shopfitter
A25: Depanning Bench Rubber Replacement | B25: Install onto the existing depanning bench Affix by silicone | D25: Shopfitter
A26: Kwik - Lok Machine | B26: Installation location as per Control Plan | C26: Y | D26: Shopfitter
A27: Microwave | B27: Install onto microwave shelf as per control plan | C27: Y | D27: Shopfitter
A28: Microwave Shelf | B28: Relocated microwave shelf as per control plan | D28: Shopfitter
A29: Mobile Stainless Steel Benches | B29: Locate as per control plan | C29: Y | D29: Shopfitter
A30: Stainless Steel Brackets & Rail for Tickets | B30: Install 3 x stainless steel rail to back of bakery stainless bench for bakery tickets - store specific location may need to be confirmed by EPM pending any store specific obstructions. | C30: Y | D30: Shopfitter
A31: Stand A4 PLU | B31: Assemble and locate on the bench | D31: Shopfitter
A32: 2 Door Freezer/Fridge | B32: Allow to unpack freezer/fridge upright doors and install as per control plan | D32: Shopfitter
A33: Purpose Built Units / Infill panels | B33: Supply and install of purpose built unit / infills as per Control Plan (matches current kit standards) | C33: Y | D33: Shopfitter

Sheet Deli
A1: =Bakery!A1 -> Store Name: Woolloongabba | B1: =Bakery!B1 -> RENEWAL & NEW STORE STORE - DAY WORKS AND NIGHT WORKS
A2: =Bakery!A2 -> Store Number: 2865 | B2: =Bakery!B2 -> FITOUT PERIOD AS PER PM'S & BUILDERS PROGRAM | D2: =Bakery!D2 -> V8
A3: =Bakery!A3 -> Plan Number Tendered On: Control Plan K 10/11/21 | B3: =Bakery!B3 -> START TBA COMPLETION DATE TBA - SUBJECT TO CHANGE | D3: =Bakery!D3 -> Updated
A4: =Bakery!A4 -> Date SOW Completed: 08/02/2022 | B4: =Bakery!B4 -> Shift P to enter a Tick | D4: =Bakery!D4 -> 44082
A5: DELI
A6: Equipment | B6: Fixing method | C6: Tick | D6: Work Done By
A7: Coolroom Racking | B7: =Bakery!B7 -> Relocate if required from existing coldrooms to new location as per Control Plan Assemble new if required as per the assembly instructions and locate as per Control Plan Adjust feet to ensure racking is level Install 'SWL' stickers into clip onto each bay Dismantle and dispose of existing racking where directed | C7: Y | D7: Shopfitter
A8: Paper Towel Dispenser (Tork) | B8: =Bakery!B8 -> Installation location as per Control Plan Fixed to the wall using plugs and screws and sealed to the wall using silicon Fixed to the wall at a height of 940mm FFL (bottom) Note - store specific level may need to be confirmed by EPM pending any store specific obstructions. | C8: Y | D8: Shopfitter
A9: Cleaning Cloth Dispenser | B9: =Bakery!B9 -> Installation location as per Control Plan Fixed to the wall using plugs and screws and sealed to the wall using silicon Fixed to the wall at a height no higher than the paper towel dispenser Do not install under the draining rack / storage rack above sink | C9: Y | D9: Shopfitter
A10: Wall Bracket for Mop Rack and Brush Rack (Cleaning products) | B10: =Bakery!B10 -> Installation location as per Control Plan Fixed to the wall using plugs and screws and sealed to the wall using silicon Fixed to the wall at a height of 1500mm above floor level for both units | C10: Y | D10: Shopfitter
A11: Hose Reel Holder | B11: =Bakery!B11 -> Installation location as per Control Plan | C11: Y | D11: Shopfitter/Builder
A12: Knife Holder | B12: =Bakery!B12 -> Installation location as per Control Plan Fixed using plugs and screws Screws are not to be too tight/flush due to the knife holder design of being removable | C12: Y | D12: Shopfitter
A13: Insectocutor (Vectothor Osprey LED) | B13: Install as per Control Plan Wall mount a min of 1.8m from the base of the unit to floor level Avoid heat oil and sharp edges Use hardware provided in the kit for installation Excess power cord to be coiled neartly to required length. (Do not cut/trim power cord as this will void warranty) Install to the left of the Power supply | C13: Y | D13: Shopfitter
A14: Hairnet Dispenser | B14: Installation location as per Control Plan | C14: Y | D14: Shopfitter
A15: Prep Area - Safety Signage | B15: Install under EPM (or renewal) direction | C15: Y | D15: Shopfitter
A16: Deli Fresh Salad Board (Lazy L) | B16: Locate on the Deli counter | C16: Y | D16: Shopfitter
A17: Low Height Cabinet Gantry Rails and Signage Kit (Fresh Made Easy) | B17: Remove, stack and wrap on pallets any existing Fresh Made Easy Signage for reuse Install new or reinstall existing Gantry Rails as per Fresh Made Easy guidelines and Signage Plan Install new or reinstall existing Blank Signage backing boards onto Gantry Rails as per Fresh Made Easy Guidelines Install new or reinstall existing Inserts as per Departmental Plan and Fresh Made Easy Guidelines | C17: Y | D17: Shopfitter
A18: Full Height Cabinet G Track Pelmet and Signage (Fresh Made Easy) | B18: Remove, stack and wrap on pallets any existing Fresh Made Easy Signage for reuse Install new or reinstall existing G Track Pelmet as per Fresh Made Easy Guidelines, Signage Plan and G Track Installation Guide Install new or reinstall existing Blank Signage backing boards into Pelmet as per Fresh Made Easy Guidelines Install new or reinstall existing Signage Inserts as per Departmental Plan and Fresh Made Easy Guidelines | C18: Y | D18: Shopfitter
A19: Bulkhead Gantry Signage | B19: =Bakery!B19 -> Install Hanging Signage as per signage plan. | C19: Y | D19: Shopfitter
A20: Prepare Accessory Equipment for Checking Off in Deli | B20: Position in department for checking | C20: Y | D20: Shopfitter
A21: Can Opener | B21: Locate as per control plan Fixed to bench using screws and silicone off | D21: Shopfitter
A22: Bench Wrapper | B22: Installation location as per Control Plan | C22: Y | D22: Shopfitter
A23: Slicers | B23: Relocate existing if required as per the control plan | C23: Y | D23: Shopfitter
A24: Purpose Built Units / Infills | B24: =Bakery!B33 -> Supply and install of purpose built unit / infills as per Control Plan (matches current kit standards) | C24: Y | D24: Shopfitter
A25: Chicken Warmer Unit PBU Cladding | B25: Supply and Install PBU Tassy Oak cladding to unit as per control plan | D25: Shopfitter

Sheet Sushi
A1: =Bakery!A1 -> Store Name: Woolloongabba | B1: =Bakery!B1 -> RENEWAL & NEW STORE STORE - DAY WORKS AND NIGHT WORKS
A2: =Bakery!A2 -> Store Number: 2865 | B2: =Bakery!B2 -> FITOUT PERIOD AS PER PM'S & BUILDERS PROGRAM | D2: =Bakery!D2 -> V8
A3: =Bakery!A3 -> Plan Number Tendered On: Control Plan K 10/11/21 | B3: =Bakery!B3 -> START TBA COMPLETION DATE TBA - SUBJECT TO CHANGE | D3: =Bakery!D3 -> Updated
A4: =Bakery!A4 -> Date SOW Completed: 08/02/2022 | B4: =Bakery!B4 -> Shift P to enter a Tick | D4: =Bakery!D4 -> 44082
A5: SUSHI
A6: Equipment | B6: Fixing method | C6: Tick | D6: Work Done By
A7: Coolroom Racking | B7: =Deli!B7 -> Relocate if required from existing coldrooms to new location as per Control Plan Assemble new if required as per the assembly instructions and locate as per Control Plan Adjust feet to ensure racking is level Install 'SWL' stickers into clip onto each bay Dismantle and dispose of existing racking where directed | D7: Shopfitter
A8: Paper Towel Dispenser (Tork) | B8: =Deli!B8 -> Installation location as per Control Plan Fixed to the wall using plugs and screws and sealed to the wall using silicon Fixed to the wall at a height of 940mm FFL (bottom) Note - store specific level may need to be confirmed by EPM pending any store specific obstructions. | D8: Shopfitter
A9: Cleaning Cloth Dispenser | B9: =Deli!B9 -> Installation location as per Control Plan Fixed to the wall using plugs and screws and sealed to the wall using silicon Fixed to the wall at a height no higher than the paper towel dispenser Do not install under the draining rack / storage rack above sink | D9: Shopfitter
A10: Wall Bracket for Mop Rack and Brush Rack (Cleaning products) | B10: =Deli!B10 -> Installation location as per Control Plan Fixed to the wall using plugs and screws and sealed to the wall using silicon Fixed to the wall at a height of 1500mm above floor level for both units | D10: Shopfitter
A11: Knife Holder | B11: =Deli!B12 -> Installation location as per Control Plan Fixed using plugs and screws Screws are not to be too tight/flush due to the knife holder design of being removable | D11: Shopfitter
A12: Insectocutor | B12: =Deli!B13 -> Install as per Control Plan Wall mount a min of 1.8m from the base of the unit to floor level Avoid heat oil and sharp edges Use hardware provided in the kit for installation Excess power cord to be coiled neartly to required length. (Do not cut/trim power cord as this will void warranty) Install to the left of the Power supply | D12: Shopfitter
A13: Hairnet Dispenser | B13: =Deli!B14 -> Installation location as per Control Plan | D13: Shopfitter
A14: Prepare Accessory Equipment for Checking Off in Sushi | B14: Position equipment in department for checking off by AFC or Sushi franchisee operator | D14: Shopfitter
A15: Demo Desk | B15: Install as per installation guidelines and locate in department | D15: Shopfitter
A16: Merchandiser Unit | B16: Install as per installation guidelines and locate as per control plan | D16: Shopfitter
A17: Purpose Built Units | B17: =Deli!B24 -> Supply and install of purpose built unit / infills as per Control Plan (matches current kit standards) | D17: Shopfitter

Sheet Seafood
A1: =Bakery!A1 -> Store Name: Woolloongabba | B1: =Bakery!B1 -> RENEWAL & NEW STORE STORE - DAY WORKS AND NIGHT WORKS
A2: =Bakery!A2 -> Store Number: 2865 | B2: =Bakery!B2 -> FITOUT PERIOD AS PER PM'S & BUILDERS PROGRAM | D2: =Bakery!D2 -> V8
A3: =Bakery!A3 -> Plan Number Tendered On: Control Plan K 10/11/21 | B3: =Bakery!B3 -> START TBA COMPLETION DATE TBA - SUBJECT TO CHANGE | D3: =Bakery!D3 -> Updated
A4: =Sushi!A4 -> Date SOW Completed: 08/02/2022 | B4: =Bakery!B4 -> Shift P to enter a Tick | D4: =Bakery!D4 -> 44082
A5: SEAFOOD
A6: Equipment | B6: Fixing method | C6: Tick | D6: Work Done By
A7: Coolroom Racking/Freezer Room | B7: =Sushi!B7 -> Relocate if required from existing coldrooms to new location as per Control Plan Assemble new if required as per the assembly instructions and locate as per Control Plan Adjust feet to ensure racking is level Install 'SWL' stickers into clip onto each bay Dismantle and dispose of existing racking where directed | C7: Y | D7: Shopfitter
A8: Paper Towel Dispenser (Tork) | B8: =Sushi!B8 -> Installation location as per Control Plan Fixed to the wall using plugs and screws and sealed to the wall using silicon Fixed to the wall at a height of 940mm FFL (bottom) Note - store specific level may need to be confirmed by EPM pending any store specific obstructions. | C8: Y | D8: Shopfitter
A9: Cleaning Cloth Dispenser | B9: =Sushi!B9 -> Installation location as per Control Plan Fixed to the wall using plugs and screws and sealed to the wall using silicon Fixed to the wall at a height no higher than the paper towel dispenser Do not install under the draining rack / storage rack above sink | C9: Y | D9: Shopfitter
A10: Wall Bracket for Mop Rack and Brush Rack (Cleaning products) | B10: =Sushi!B10 -> Installation location as per Control Plan Fixed to the wall using plugs and screws and sealed to the wall using silicon Fixed to the wall at a height of 1500mm above floor level for both units | C10: Y | D10: Shopfitter
A11: Hose Reel Holder | B11: =Deli!B11 -> Installation location as per Control Plan | C11: Y | D11: Shopfitter/Builder
A12: Knife Holder | B12: =Deli!B12 -> Installation location as per Control Plan Fixed using plugs and screws Screws are not to be too tight/flush due to the knife holder design of being removable | C12: Y | D12: Shopfitter
A13: Insectocutor (Vectothor Osprey LED) | B13: Install as per Control Plan Install to the left of the Power supply Wall mount a min of 1.8m from the base of the unit to floor level Avoid heat oil and sharp edges Use hardware provided in the kit for installation Excess power cord to be coiled neartly to required length. (Do not cut/trim power cord as this will void warranty) | C13: Y | D13: Shopfitter
A14: Hairnet Dispenser | B14: =Sushi!B13 -> Installation location as per Control Plan | C14: Y | D14: Shopfitter
A15: Low Height Cabinet Gantry Rails and Signage Kit (Fresh Made Easy) | B15: =Deli!B17 -> Remove, stack and wrap on pallets any existing Fresh Made Easy Signage for reuse Install new or reinstall existing Gantry Rails as per Fresh Made Easy guidelines and Signage Plan Install new or reinstall existing Blank Signage backing boards onto Gantry Rails as per Fresh Made Easy Guidelines Install new or reinstall existing Inserts as per Departmental Plan and Fresh Made Easy Guidelines | C15: Y | D15: Shopfitter
A16: Full Height Cabinet G Track Pelmet and Signage (Fresh Made Easy) | B16: =Deli!B18 -> Remove, stack and wrap on pallets any existing Fresh Made Easy Signage for reuse Install new or reinstall existing G Track Pelmet as per Fresh Made Easy Guidelines, Signage Plan and G Track Installation Guide Install new or reinstall existing Blank Signage backing boards into Pelmet as per Fresh Made Easy Guidelines Install new or reinstall existing Signage Inserts as per Departmental Plan and Fresh Made Easy Guidelines | C16: Y | D16: Shopfitter
A17: Prepare Accessory Equipment for Checking Off in Seafood | B17: Position equipment in department for checking | C17: Y | D17: Shopfitter
A18: Bench Wrapper | B18: Locate as per control plan | C18: Y | D18: Shopfitter
A19: Purpose Built Units | B19: =Sushi!B17 -> Supply and install of purpose built unit / infills as per Control Plan (matches current kit standards) | C19: Y | D19: Shopfitter

Sheet Meat
A1: =Bakery!A1 -> Store Name: Woolloongabba | B1: =Bakery!B1 -> RENEWAL & NEW STORE STORE - DAY WORKS AND NIGHT WORKS
A2: =Bakery!A2 -> Store Number: 2865 | B2: =Bakery!B2 -> FITOUT PERIOD AS PER PM'S & BUILDERS PROGRAM | D2: =Bakery!D2 -> V8
A3: =Bakery!A3 -> Plan Number Tendered On: Control Plan K 10/11/21 | B3: =Bakery!B3 -> START TBA COMPLETION DATE TBA - SUBJECT TO CHANGE | D3: =Bakery!D3 -> Updated
A4: =Seafood!A4 -> Date SOW Completed: 08/02/2022 | B4: =Bakery!B4 -> Shift P to enter a Tick | D4: =Bakery!D4 -> 44082
A5: MEAT
A6: Equipment | B6: Fixing method | C6: Tick | D6: Work Done By
A7: Coolroom Racking/Dry Store Racking | B7: =Seafood!B7 -> Relocate if required from existing coldrooms to new location as per Control Plan Assemble new if required as per the assembly instructions and locate as per Control Plan Adjust feet to ensure racking is level Install 'SWL' stickers into clip onto each bay Dismantle and dispose of existing racking where directed | C7: Y | D7: Shopfitter
A8: Paper Towel Dispenser (Tork) | B8: =Seafood!B8 -> Installation location as per Control Plan Fixed to the wall using plugs and screws and sealed to the wall using silicon Fixed to the wall at a height of 940mm FFL (bottom) Note - store specific level may need to be confirmed by EPM pending any store specific obstructions. | C8: Y | D8: Shopfitter
A9: Cleaning Cloth Dispenser | B9: =Seafood!B9 -> Installation location as per Control Plan Fixed to the wall using plugs and screws and sealed to the wall using silicon Fixed to the wall at a height no higher than the paper towel dispenser Do not install under the draining rack / storage rack above sink | C9: Y | D9: Shopfitter
A10: Wall Bracket for Mop Rack and Brush Rack (Cleaning products) | B10: =Seafood!B10 -> Installation location as per Control Plan Fixed to the wall using plugs and screws and sealed to the wall using silicon Fixed to the wall at a height of 1500mm above floor level for both units | C10: Y | D10: Shopfitter
A11: Hose Reel Holder | B11: =Seafood!B11 -> Installation location as per Control Plan | C11: Y | D11: Shopfitter/Builder
A12: Knife Holder | B12: =Seafood!B12 -> Installation location as per Control Plan Fixed using plugs and screws Screws are not to be too tight/flush due to the knife holder design of being removable | C12: Y | D12: Shopfitter
A13: Insectocutor (Vectothor Osprey LED) | B13: Install as per Control Plan Install to the left of the Power supply Wall mount a min of 1.8m from the base of the unit to floor level Avoid heat oil and sharp edges Use hardware provided in the kit for installation Excess power cord to be coiled neartly to required length. (Do not cut/trim power cord as this will void warranty) | C13: Y | D13: Shopfitter
A14: Hairnet Dispenser | B14: =Seafood!B14 -> Installation location as per Control Plan | C14: Y | D14: Shopfitter
A15: Low Height Cabinet Gantry Rails and Signage Kit (Fresh Made Easy) | B15: =Seafood!B15 -> Remove, stack and wrap on pallets any existing Fresh Made Easy Signage for reuse Install new or reinstall existing Gantry Rails as per Fresh Made Easy guidelines and Signage Plan Install new or reinstall existing Blank Signage backing boards onto Gantry Rails as per Fresh Made Easy Guidelines Install new or reinstall existing Inserts as per Departmental Plan and Fresh Made Easy Guidelines | C15: Y | D15: Shopfitter
A16: Full Height Cabinet G Track Pelmet and Signage (Fresh Made Easy) | B16: =Seafood!B16 -> Remove, stack and wrap on pallets any existing Fresh Made Easy Signage for reuse Install new or reinstall existing G Track Pelmet as per Fresh Made Easy Guidelines, Signage Plan and G Track Installation Guide Install new or reinstall existing Blank Signage backing boards into Pelmet as per Fresh Made Easy Guidelines Install new or reinstall existing Signage Inserts as per Departmental Plan and Fresh Made Easy Guidelines | C16: Y | D16: Shopfitter
A17: Prepare Accessory Equipment for Checking Off in Meat | B17: Position in department for checking | C17: Y | D17: Shopfitter
A18: Stainless Steel and Cutting Benches | B18: Locate as per control plan Adjust feet to ensure benches are level | D18: Shopfitter
A19: Holder Info Card 2 Pocket | B19: Install and clip over the wire front of the meat cabinet and shelves | D19: Shopfitter
A20: Wall Hook for Ring Spanner | B20: Fixed to the wall near the mincer. Fixed to the wall using plugs and screws and sealed to the wall using silicon. Fixed to the wall at a height of 1800mm above floor level | D20: Shopfitter
A21: Purpose Built Units | B21: =Seafood!B19 -> Supply and install of purpose built unit / infills as per Control Plan (matches current kit standards) | C21: Y | D21: Shopfitter

Sheet Fruit & Veg
A1: =Bakery!A1 -> Store Name: Woolloongabba | B1: =Bakery!B1 -> RENEWAL & NEW STORE STORE - DAY WORKS AND NIGHT WORKS
A2: =Bakery!A2 -> Store Number: 2865 | B2: =Bakery!B2 -> FITOUT PERIOD AS PER PM'S & BUILDERS PROGRAM | D2: =Bakery!D2 -> V8
A3: =Bakery!A3 -> Plan Number Tendered On: Control Plan K 10/11/21 | B3: =Bakery!B3 -> START TBA COMPLETION DATE TBA - SUBJECT TO CHANGE | D3: =Bakery!D3 -> Updated
A4: =Meat!A4 -> Date SOW Completed: 08/02/2022 | B4: =Bakery!B4 -> Shift P to enter a Tick | D4: =Bakery!D4 -> 44082
A5: PRODUCE MERCHANDISING
A6: Equipment | B6: Fixing method | C6: Tick | D6: Work Done By
A7: Paper Towel Dispenser (Tork) | B7: =Meat!B8 -> Installation location as per Control Plan Fixed to the wall using plugs and screws and sealed to the wall using silicon Fixed to the wall at a height of 940mm FFL (bottom) Note - store specific level may need to be confirmed by EPM pending any store specific obstructions. | C7: Y | D7: Shopfitter
A8: Cleaning Cloth Dispenser | B8: =Meat!B9 -> Installation location as per Control Plan Fixed to the wall using plugs and screws and sealed to the wall using silicon Fixed to the wall at a height no higher than the paper towel dispenser Do not install under the draining rack / storage rack above sink | C8: Y | D8: Shopfitter
A9: Wall Bracket for Mop Rack and Brush Rack (Cleaning products) | B9: =Meat!B10 -> Installation location as per Control Plan Fixed to the wall using plugs and screws and sealed to the wall using silicon Fixed to the wall at a height of 1500mm above floor level for both units | C9: Y | D9: Shopfitter
A10: Hose Reel Holder | B10: =Meat!B11 -> Installation location as per Control Plan | C10: Y | D10: Shopfitter/Builder
A11: Knife Holder | B11: =Meat!B12 -> Installation location as per Control Plan Fixed using plugs and screws Screws are not to be too tight/flush due to the knife holder design of being removable | C11: Y | D11: Shopfitter
A12: Insectocutor | B12: Suspended from the ceiling using stainless steel crimp wire Suspended from the ceiling at a height of minimum of 2400mm above floor level as shown on control plan Installation location as per Control Plan | C12: Y | D12: Shopfitter
A13: Hairnet Dispenser | B13: =Meat!B14 -> Installation location as per Control Plan | C13: Y | D13: Shopfitter
A14: Ambient Produce Tables (inc Banana End, Promo Bins and Avocado Table) | B14: Assemble as per the assembly guidelines and locate as per control plan Dismantle and dispose of existing fixtures where directed. (Renewals only) Relocate existing fixtures, if applicable, as per control plan (Renewals only) Ensure end units with bins have doors facing towards rear of store as per control plan | C14: Y | D14: Shopfitter
A15: Berry Case Cladding | B15: Assemble as per the assembly guidelines and install around Berry Case | C15: Y | D15: Shopfitter
A16: Nut Unit Display | B16: Assemble as per the assembly guidelines and locate as per the control plan | C16: Y | D16: Shopfitter
A17: Gantry Rails for Ambient Produce Tables (inc Banana End, Promo Bins, Avocado Table and Berry Case) | B17: Install as per Produce Guidelines | C17: Y | D17: Shopfitter
A18: Timber Price Signage for Ambient Tables | B18: 800mm Boards - Install one per Table and End Table 1100mm Boards - Install one per Promo Table, Avocado Table and Berry Case | C18: Y | D18: Shopfitter
A19: Inspirational Signage for Ambient Tables | B19: Locate on Produce Tables for Store Installation | C19: Y | D19: Shopfitter
A20: Promo Bin Flip Price Signage | B20: Install on front of Promo Bins, Avocado Bin and Berry Cladding | C20: Y | D20: Shopfitter
A21: Low Height Cabinet Gantry Rails and Signage Kit (Fresh Made Easy) | B21: =Meat!B15 -> Remove, stack and wrap on pallets any existing Fresh Made Easy Signage for reuse Install new or reinstall existing Gantry Rails as per Fresh Made Easy guidelines and Signage Plan Install new or reinstall existing Blank Signage backing boards onto Gantry Rails as per Fresh Made Easy Guidelines Install new or reinstall existing Inserts as per Departmental Plan and Fresh Made Easy Guidelines | C21: Y | D21: Shopfitter
A22: Full Height Cabinet G Track Pelmet and Signage (Fresh Made Easy) | B22: =Meat!B16 -> Remove, stack and wrap on pallets any existing Fresh Made Easy Signage for reuse Install new or reinstall existing G Track Pelmet as per Fresh Made Easy Guidelines, Signage Plan and G Track Installation Guide Install new or reinstall existing Blank Signage backing boards into Pelmet as per Fresh Made Easy Guidelines Install new or reinstall existing Signage Inserts as per Departmental Plan and Fresh Made Easy Guidelines | C22: Y | D22: Shopfitter
A23: Local Source Tables | B23: Assemble as per the assembly guidelines and locate as per the control plan | C23: Y | D23: Shopfitter
A24: Floral units / bag stand | B24: Locate as per Control Plan | C24: Y | D24: Shopfitter
A25: Free Fruit for Kids Stand | B25: Locate as per Control Plan | C25: Y | D25: Shopfitter
A26: Hanging Scale Stand and Extension Pole for Produce Tables | B26: Install as per install guidelines and locate as per Control Plan Relocate existing as per control plan (Renewals Only) | C26: Y | D26: Shopfitter
A27: Bag Holders | B27: Install as per Control Plan onto Ambient Tables Install cabinet bag holders | C27: Y | D27: Shopfitter
A28: Mushroom Bag Holder for Cabinets | B28: Install into mushroom bay | C28: Y | D28: Shopfitter
A29: Console Wrapper on Stand | B29: Locate as per control plan | C29: Y | D29: Shopfitter
A30: Prepare Accessory Equipment for Checking Off in F&V | B30: Position equipment in department for checking | C30: Y | D30: Shopfitter
A31: Old Produce Trading Floor | B31: Dismantle and dump at the tip OR Pack and strap to be relocated to another nominated store by Operations team | C31: Y | D31: Shopfitter
A32: Produce Case Shelving | B32: Install or relocate as per EPM/Refit supplied Planogram | C32: Y | D32: Shopfitter
A33: Fogging/Misting Unit Shroud | B33: Install Fogging Shroud around the Fogging/Misting Unit on top of the case | C33: Y | D33: Shopfitter
A34: Speciality Produce Case Equipment Kits | B34: Assembled as per the assembly guidelines Layout as per EPM/Refit supplied Planogram | C34: Y | D34: Shopfitter
A35: Stainless Steel Brackets & Rail for Tickets | B35: Install 3 x 1mt stainless steel rail to produce wall. Affix to the wall with silicone | C35: Y | D35: Shopfitter
A36: Purpose Built Units / Infill panels | B36: =Meat!B21 -> Supply and install of purpose built unit / infills as per Control Plan (matches current kit standards) | C36: Y | D36: Shopfitter

Sheet Frozen Food and Dairy
A1: =Bakery!A1 -> Store Name: Woolloongabba | B1: =Bakery!B1 -> RENEWAL & NEW STORE STORE - DAY WORKS AND NIGHT WORKS
A2: =Bakery!A2 -> Store Number: 2865 | B2: =Bakery!B2 -> FITOUT PERIOD AS PER PM'S & BUILDERS PROGRAM | D2: =Bakery!D2 -> V8
A3: =Bakery!A3 -> Plan Number Tendered On: Control Plan K 10/11/21 | B3: =Bakery!B3 -> START TBA COMPLETION DATE TBA - SUBJECT TO CHANGE | D3: =Bakery!D3 -> Updated
A4: =Bakery!A4 -> Date SOW Completed: 08/02/2022 | B4: =Bakery!B4 -> Shift P to enter a Tick | D4: =Bakery!D4 -> 44082
A5: FROZEN FOOD/DAIRY
A6: Equipment | B6: Fixing method | C6: Tick | D6: Work Done By
A7: Coolroom Racking for Freezer | B7: =Meat!B7 -> Relocate if required from existing coldrooms to new location as per Control Plan Assemble new if required as per the assembly instructions and locate as per Control Plan Adjust feet to ensure racking is level Install 'SWL' stickers into clip onto each bay Dismantle and dispose of existing racking where directed | C7: Y | D7: Shopfitter
A8: Coolroom Racking for Dairy | B8: =B7 -> Relocate if required from existing coldrooms to new location as per Control Plan Assemble new if required as per the assembly instructions and locate as per Control Plan Adjust feet to ensure racking is level Install 'SWL' stickers into clip onto each bay Dismantle and dispose of existing racking where directed | C8: Y | D8: Shopfitter
A9: Wall Bracket for Mop Rack (Cleaning products) | B9: ='Fruit & Veg'!B9 -> Installation location as per Control Plan Fixed to the wall using plugs and screws and sealed to the wall using silicon Fixed to the wall at a height of 1500mm above floor level for both units | C9: Y | D9: Shopfitter
A10: Prepare Accessory Equipment for Checking Off in Perishables | B10: Position equipment in Dairy coldroom for checking | D10: Shopfitter
A11: Freezer Jacket Hanging Hooks | B11: Allow to supply a 800mm x 40mm gal rail with 4 hooks to hang freezer jackets. Install at 1700mm FFL. Screw and silicone this to the wall | C11: Y | D11: Shopfitter
A12: Full Height Cabinet G Track Pelmet and Signage | B12: Remove, stack and wrap on pallets any existing Fresh Made Easy Signage for reuse Install G Track Pelmet as per Signage Plan and G Track Installation Guidelines Install blank and price point signage backing boards into Pelmet as per Departmental Plan | C12: Y | D12: Shopfitter
A13: Freezer Coffin G Track Pelmet | B13: Remove, stack and wrap on pallets any existing Fresh Made Easy Signage for reuse Install G Track Pelmet as per Signage Plan and G Track Installation Guidelines Install blank and price point signage backing boards into Pelmet as per Departmental Plan | D13: Shopfitter
A14: Purpose Built Units / Infill panels | B14: ='Fruit & Veg'!B36 -> Supply and install of purpose built unit / infills as per Control Plan (matches current kit standards) | C14: Y | D14: Shopfitter

Sheet Liquor
A1: =Bakery!A1 -> Store Name: Woolloongabba | B1: =Bakery!B1 -> RENEWAL & NEW STORE STORE - DAY WORKS AND NIGHT WORKS
A2: =Bakery!A2 -> Store Number: 2865 | B2: =Bakery!B2 -> FITOUT PERIOD AS PER PM'S & BUILDERS PROGRAM | D2: =Bakery!D2 -> V8
A3: =Bakery!A3 -> Plan Number Tendered On: Control Plan K 10/11/21 | B3: =Bakery!B3 -> START TBA COMPLETION DATE TBA - SUBJECT TO CHANGE | D3: =Bakery!D3 -> Updated
A4: =Bakery!A4 -> Date SOW Completed: 08/02/2022 | B4: =Bakery!B4 -> Shift P to enter a Tick | D4: =Bakery!D4 -> 44082
A5: LIQUOR
A6: Equipment | B6: Fixing method | C6: Tick | D6: Work Done By
A7: Coolroom Shelving | B7: Installed OR Relocated as per the control plan Installed level Dismantle and dispose of existing racking where directed. | D7: Shopfitter
A8: Paper Towel Dispenser (Tork) | B8: Locate near each hand wash basin Fixed to the wall using plugs and screws and sealed to the wall using silicon Fixed to the wall at a height of 940mm FFL (bottom) - store specific level may need to be to be confirmed by EPM pending any store specific obstructions. | D8: Shopfitter
A9: Counter Cash Wrap | B9: Installed as per the control plan Installed level All accessories to be installed as per specification Dismantle and dispose of existing Refurbs Only | D9: Shopfitter
A10: Cigarette / Miniature Units | B10: Installed as per the control plan Installed level All accessories to be installed as per specification Dismantle and dispose of existing Refurbs Only | D10: Shopfitter
A11: Cash Vacuum Pole | B11: Fixed to the wall behind the cash wrap Fixed to the wall using brackets, plugs and screws | D11: Shopfitter
A12: Trading Floor Fixtures (High and Low Profile) | B12: Assembled as per the assembly instructions Adjust feet to ensure shelving is level Locate as per control plan | D12: Shopfitter
A13: Existing Trading Floor Fixtures Wall Only | B13: Allow to temporary remove/relocate for wall painting Reinstate as per control plan when painting is completed Adjust feet to ensure shelving is level Locate as per control plan | D13: Shopfitter
A14: Security Mirrors | B14: Installed in consultation with store manager Locate to assist staff in obtaining a clear view of all areas of the trading floor | D14: Shopfitter
A15: Mobile First Aid Kit | B15: Locate in the cash wrap | D15: Shopfitter
A16: Liquor Signage | B16: Installed as per departmental signage plan Hanging signage to be suspended using stainless steel crimp wire Suspended at a height of 2100mm above floor level (to underside of the sign) | D16: Shopfitter
A17: -External Anti Theft A0 Frames | B17: Fixed to the glass shopfront using double sided tape as provided with the snap frames Fixed to the glass shopfront at a height of 1200mm above ground level (to the underside of the sign) | D17: Shopfitter
A18: -Legal Notice Panel | B18: Fixed to the wall using plugs and screws Fixed to the wall at a height of 1200mm above floor level (to the underside of the sign) on a wall adjacent to the cash wrap | D18: Shopfitter
... A25: Purpose Built Units / Infill panels | B25: Supply and install of purpose built unit / infills in Produce dept as per control plan | D25: Shopfitter

Sheet Trading Floor
A1: =Bakery!A1 -> Store Name: Woolloongabba | B1: =Bakery!B1 -> RENEWAL & NEW STORE STORE - DAY WORKS AND NIGHT WORKS
A2: =Bakery!A2 -> Store Number: 2865 | B2: =Bakery!B2 -> FITOUT PERIOD AS PER PM'S & BUILDERS PROGRAM | D2: =Bakery!D2 -> V8
A3: =Bakery!A3 -> Plan Number Tendered On: Control Plan K 10/11/21 | B3: =Bakery!B3 -> START TBA COMPLETION DATE TBA - SUBJECT TO CHANGE | D3: =Bakery!D3 -> Updated
A4: =Bakery!A4 -> Date SOW Completed: 08/02/2022 | B4: =Bakery!B4 -> Shift P to enter a Tick | D4: =Bakery!D4 -> 44082
A5: SUPERMARKET MAIN TRADING FLOOR
A6: Equipment | B6: Fixing method | C6: Tick | D6: Work Done By
A7: Trading Floor Shelving (New Store) | B7: Installation of primary and secondary fixtures throughout the trading floor as per Control Plan, Departmental Plan and Refit Supplied POG's Each bay of punch panel to be Tec screwed (x2) to each T-post. Tec screw locations are notch 34 (1st notch of top panel) Capping shelves to be installed as per standard. Install 510 base supports (drink aisle) Install 750 shelving for Papergoods Install Data Stripping onto all Shelves | C7: Y | D7: Shopfitter
A8: Trading Floor Shelving (Renewal Strip and Build) | B8: Removal of all existing Trading Floor equipment offsite and to be recycle/or dumped unless instructed otherwise Installation of primary fixtures throughout the trading floor as per Control Plan and Departmental Plan. Each bay of punch panel to be Tec screwed (x2) to each T-post. Tec screw locations are notch 34 (1st notch of top panel) Capping shelves to be installed as per standard. Install 510 base supports (drink aisle) | D8: Shopfitter
A9: Trading Floor Shelving (510 Secondary Swap) | B9: Installation of Primary Equipment as per Control Plan and Departmental Plan Capping shelves to be installed as per standard. Replace missing post plugs Check gondolas to be removed / relocated / disposed - compare control plan against existing plan Removal of existing equipment offsite and to be recycle/or dumped unless instructed otherwise | D9: Shopfitter
A10: Heavy Duty Shelving to Drinks Aisle | B10: Install new Heavy Duty shelving to drinks aisle as indicated on Control Plan as per installation guidelines | D10: Shopfitter
A11: Outrigger Removal | B11: Remove and dump old outriggers from all fixtures. | C11: Y | D11: Shopfitter
A12: Pinning T-post | B12: Every second T-post foot to be pinned down and on one side only of gondola for HBB Aisle All single sided fixtures to be pinned down throughout trading floor | C12: Y | D12: Shopfitter
A13: Workstation Gondola/Freestanding | B13: Install workstation as per installation guidelines and located as per control plan | C13: Y | D13: Shopfitter
A14: D pallet kit | B14: Install D pallet kit as per departmental plan | D14: Shopfitter
A15: Capping Shelves | B15: Install capping shelves and brackets as per Capping Shelf Standard | C15: Y | D15: Shopfitter
A16: Rolling Existing Gondolas | B16: Please allow to roll gondolas as per builders program - Check with each builder for program when quoting. Relocate Promo and BEM Ends when moving gondolas. Temporary relocate aisle signs as required when rolling gondolas | D16: Shopfitter
A17: Existing Wall Gondolas | B17: Allow to remove or temporarily relocate for wall painting Reinstate as per control plan once painted | D17: Shopfitter
A18: Cut Shelves | B18: Allow to cut shelves or baskets around all columns where they appear in the gondolas. Allow to brace the cut shelves to the column with angle aluminium. | C18: Y
A19: Remove Light Boxes | B19: Remove existing light boxes (in conjunction with an electrician) | D19: Shopfitter
A20: Promo Ends | B20: Remove existing, recycle/or dumped unless instructed otherwise Assemble new as per assembly instructions and locate as per the control plan Allow for retro fitting of all Pelmet Types and Capping Shelf Brackets for support beam | C20: Y | D20: Shopfitter
A21: V Ticket Frames | B21: Fitted to all ends as per control plan (ensure that the frames are installed level) | C21: Y | D21: Shopfitter
A22: Aisle Signs | B22: Install as per the signage plan Suspended from the purlins using stainless steel crimp wire, making sure that it doesn't interfere with overhead lighting at a height of 2400mm above floor level (to the underside of the sign) Category name and number panels to be fitted Wipe down and remove fingerprints Note - When removing existing Aisle Signs check ceiling grid for existing timber supports sitting on top of grid and remove if found Note - when rolling gondolas to temp locations until relays are complete please plan to relocate existing aisle signs as required centred to temp aisles prior to store opening next trading day. | C22: Y | D22: Shopfitter
A23: Street Signs | B23: Install to the top of the T-post as per departmental plan (min 5 bays between street signs and start in the 2nd bay. If the Planogram is more than 15 bays add a 2nd street sign with same name) Slide down arm into T-post and utilise square infill provided or back to back street sign arm | C23: Y | D23: Shopfitter
A24: Display Units | B24: DVD unit - assemble & install as per departmental plan Magazine display units - assemble & install as per departmental plan Scrum units and accessories - assemble & install as per departmental plan. Install graphic inserts for base/mid shelves | C24: Y | D24: Shopfitter
A25: HBB Pelmet | B25: Install HBB Pelmet as per installation guidelines and locate as per Departmental Plan | C25: Y | D25: Shopfitter
A26: HBB G Track Pelmet and Signage Inserts | B26: Install G Track Pelmet and Signage Inserts as per Signage Plan, Departmental Plan and HBB G Track Installation Guidelines | C26: Y | D26: Shopfitter
A27: Cosmetics DLP Signage | B27: Install DLP Cosmetics Signage inserts into G Track Pelmet Connect daisy chain power connections to builder supplied GPO's as per installation guidelines | D27: Shopfitter
A28: HBB Illuminated Pelmet | B28: Remove and dump redundant HBB metal pelmet and covers. Install new illuminated Pelmet as per installation guidelines Connect daisy chain power connections to builder supplied GPO's as per installation guidelines | C28: Y | D28: Shopfitter
A29: 3.0 Cosmetics Unit | B29: Remove and dump redundant cosmetic equipment Install new 3.0 Cosmetics Unit as per installation guidelines Connect daisy chain power connections to builder supplied GPO's as per installation guidelines | C29: Y | D29: Shopfitter
A30: HBB Halo Light | B30: Install new HBB Halo Light as per installation guidelines | C30: Y
A31: HBB Fins | B31: Install HBB Sigange Fins | C31: Y | D31: Shopfitter
A32: Health Food Pelmet | B32: Install Health Food Pelmet as per installation guidelines and locate as per Departmental Plan and guidence from Refit for descriptions | C32: Y | D32: Shopfitter
A33: Events Pelmet | B33: Install Events Pelmet as per installation guidelines and locate as per Departmental Plan | C33: Y
A34: Gift Card End and Signage | B34: Install or relocate as per control plan Assembled as per install guidelines | C34: Y | D34: Shopfitter
A35: End Panels & Corner Box | B35: Supply & install melamine end panels to the ends of all single sided gondola's where they do not abut a wall and allow for boxing out corners | C35: Y | D35: Shopfitter
A36: Purpose Built Units / Infill panels | B36: Supply and install of purpose built unit / infill's control plan | C36: Y | D36: Shopfitter
A37: Paper Towel Dispenser (Tork) | B37: Install paper towel dispensers as per control plan | C37: Y | D37: Shopfitter

Sheet Checkout Area
A1: =Bakery!A1 -> Store Name: Woolloongabba | B1: =Bakery!B1 -> RENEWAL & NEW STORE STORE - DAY WORKS AND NIGHT WORKS
A2: =Bakery!A2 -> Store Number: 2865 | B2: =Bakery!B2 -> FITOUT PERIOD AS PER PM'S & BUILDERS PROGRAM | D2: =Bakery!D2 -> V8
A3: =Bakery!A3 -> Plan Number Tendered On: Control Plan K 10/11/21 | B3: =Bakery!B3 -> START TBA COMPLETION DATE TBA - SUBJECT TO CHANGE | D3: =Bakery!D3 -> Updated
A4: =Bakery!A4 -> Date SOW Completed: 08/02/2022 | B4: =Bakery!B4 -> Shift P to enter a Tick | D4: =Bakery!D4 -> 44082
A5: CHECKOUT AREA
A6: Equipment | B6: Fixing method | C6: Tick | D6: Work Done By
A7: Checkouts | B7: As per installation instructions Locate as per store control plan Bolted together to make a neat visual finish Installed level All accessory items to be installed as per the installation instructions Fixed to the floor using construction adhesive Check that conveyor is operational prior to leaving site from installation Install There's no need to lift heavy items signage on every conveyor Shopfitters to remove all rubbish Install new Customer Centric Checkout Ends | C7: Y | D7: Shopfitter
A8: Dismantle and remove existing Front End equipment | B8: Dismantle and dispose as required - all redundant equipment to be removed from site | D8: Shopfitter
A9: Service Desk Area | B9: As per installation instructions Locate as per store control plan Installed level All accessory items to be installed as per the installation instructions, locate smoke acrylic dividers and isolate for store team Connect power source to Telco unit (by electrical contractor) | C9: Y | D9: Shopfitter
A10: Hand Operated Claxon Siren | B10: Locate in the cupboards of the Service Desk | C10: Y | D10: Shopfitter
A11: Frame For Smoking Kills Sign (State Specific) | B11: Install frame for the sign on bench top over cig units | C11: Y | D11: Shopfitter
A12: Express Checkouts | B12: As per installation instructions Bolted together to make a neat visual finish All accessory items to be installed as per the specification | C12: Y | D12: Shopfitter
A13: Purpose Built Unit | B13: Supply and install of purpose built unit / infill's as per Control Plan (matches current kit standards) | C13: Y | D13: Shopfitter
A14: Tensabarriers | B14: Installed as per installation instructions | C14: Y | D14: Shopfitter
A15: Checkout Service Poles | B15: Installed into recessed section of the checkout and aligned with the ceiling tiles as per installation instructions. Top hat installed to secure poles and cover installation marks (ensure it is inverted into ceiling tiles) Cut and install / or modify to suit the store | C15: Y | D15: Shopfitter
A16: Checkout ID Lights | B16: Fixed to the service poles as per installation instructions Fixed to the service poles using screws and brackets into the pre-drilled holes on the checkout service pole Connected to power source from service pole (by electrical contractor) | C16: Y | D16: Shopfitter
A17: Checkout Merchandisers (Std, Exp & ACO and Mini Merch ACO units) | B17: Install as per control plan. Ensure that all lights are operational | C17: Y | D17: Shopfitter
A18: Checkout and ACO Screen's | B18: Install new or relocate existing Register and ACO's Screens | C18: Y | D18: Shopfitter
A19: Stainless Steel Railing | B19: Fixed to the floor using stainless steel counter sunk dyna-bolts (supplied by shopfitter). Installed as per the store control drawing | C19: Y | D19: Shopfitter
A20: FOS Hand Sanitiser | B20: Locate as per control plan. | C20: Y | D20: Shopfitter
... A32: Community Notice Board | B32: Installed as per Signage plan | C32: Y | D32: Shopfitter
A33: Plaque Indigenous Acknowledgement | B33: Installed as per Signage plan | C33: Y
A34: Cafe | B34: Locate items as per control plan | D34: Shopfitter
A35: Hanging Rails across full store Front end, Fresh Foods and Trading floor | B35: Suspended from the purlins as per Signage Plan (approximately 20-30 per Store) | C35: Y | D35: Shopfitter
A36: AED Unit | B36: Installed as per Control Plan | C36: Y | D36: Shopfitter

Sheet Team Room and Amenities
A1: =Bakery!A1 -> Store Name: Woolloongabba | B1: =Bakery!B1 -> RENEWAL & NEW STORE STORE - DAY WORKS AND NIGHT WORKS
A2: =Bakery!A2 -> Store Number: 2865 | B2: =Bakery!B2 -> FITOUT PERIOD AS PER PM'S & BUILDERS PROGRAM | D2: =Bakery!D2 -> V8
A3: =Bakery!A3 -> Plan Number Tendered On: Control Plan K 10/11/21 | B3: =Bakery!B3 -> START TBA COMPLETION DATE TBA - SUBJECT TO CHANGE | D3: =Bakery!D3 -> Updated
A4: =Bakery!A4 -> Date SOW Completed: 08/02/2022 | B4: =Bakery!B4 -> Shift P to enter a Tick | D4: =Bakery!D4 -> 44082
A5: TEAM DINING ROOM
A6: Equipment | B6: Fixing method | C6: Tick | D6: Work Done By
A7: First Aid Kit | B7: Locate as per control plan Fixed to the wall using plugs and screws and sealed to the wall using silicon Fixed to the wall at a height of 1270mm above floor level | C7: Y | D7: Shopfitter
A8: Lunchroom Tables and Chairs | B8: Assembled as per installation instructions and locate as per Control Plan. Relocate or remove existing | C8: Y | D8: Shopfitter
A9: Lounge Chairs & Coffee Table | B9: Locate as per control plan | C9: Y | D9: Shopfitter
A10: Fridge | B10: Locate as per control plan Relocate or remove existing | C10: Y | D10: Shopfitter
A11: Microwave | B11: Locate on the kitchen bench or In purpose built joinery void space in Kitchenette | C11: Y | D11: Shopfitter
A12: 55 inch TV on Wall Bracket (VOC) | B12: Fixed to wall as per control plan Bracket installed as per instructions located in box | D12: Shopfitter
A13: 55 inch TV on Wall Bracket (Free to Air) | B13: Fixed to wall as per control plan Bracket installed as per instructions located in box | C13: Y | D13: Shopfitter
A14: Island Waste Bins | B14: Locate in lunchroom under Island Kitchen Bench | C14: Y | D14: Shopfitter
A15: Paper Towel Dispenser (Tork) | B15: Locate near each hand wash basin Fixed to the wall using plugs and screws and sealed to the wall using silicon Locate in wash area - 1 in each toilet and 1 in kitchen near the sink | C15: Y | D15: Shopfitter
A16: Door Sign Kit as supplied | B16: Installed as per signage application guide Fixed to the door at 1250mm from finished floor level (to underside of the sign as per AN standard) | C16: Y | D16: Shopfitter
A17: Cubby House | B17: Assembled as per installation instructions and locate as per Control Plan.
A18: AMENITIES & CLEANERS ROOM
A19: Equipment | B19: Fixing method | C19: Tick | D19: Work Done By
A20: Lockers | B20: Assembled as per installation instructions and locate as per Control Plan. Relocate or remove existing | C20: Y | D20: Shopfitter
A21: Shelf with Hanging Coat Rail | B21: Fixed to the lockers as per control plan | C21: Y | D21: Shopfitter
A22: Team bench | B22: Assembled as per installation instructions and locate as per Control Plan. | C22: Y | D22: Shopfitter
A23: Cleaning Room Shelving | B23: Relocate if required from existing location to new location as per Control Plan Assemble new if required as per the assembly instructions and locate as per Control Plan Adjust feet to ensure racking is level Install 'SWL' stickers into clip onto each bay Dismantle and dispose of existing racking where directed | C23: Y | D23: Shopfitter
A24: Mop & Broom Rack | B24: Locate as per control plan Fixed to the wall using plugs and screws. Fixed to the wall at a height of 1500mm above floor level | C24: Y | D24: Shopfitter
A25: Paper Towel Dispenser (Tork) | B25: Locate near each hand wash basin Fixed to the wall using plugs and screws and sealed to the wall using silicon Locate in wash area - 1 in each toilet and 1 in kitchen near the sink | C25: Y | D25: Shopfitter
A26: Wall Bracket for Mop Rack and Brush Rack (Cleaning products) | B26: Locate as per control plan Fixed to the wall using plugs and screws and sealed to the wall using silicon Fixed to the wall at a height of 1500mm above floor level for both units | C26: Y | D26: Shopfitter
A27: Door Sign Kit as supplied | B27: Installed as per signage application guide Fixed to the door at 1250mm from finished floor level (to underside of the sign as per AS standard) | C27: Y | D27: Shopfitter
A28: OFFICES
A29: Equipment | B29: Fixing method | C29: Tick | D29: Work Done By
A30: G12 Cupboard | B30: Locate as per control plan Shelving to be installed | C30: Y | D30: Shopfitter
A31: Fax Machine | B31: Locate in systems office Locate as per control plan | C31: Y | D31: Shopfitter
A32: Hand Operated Claxon Siren | B32: Locate one in general office in G12 | C32: Y | D32: Shopfitter
A33: Filing Cabinets | B33: Locate as per control plan | C33: Y | D33: Shopfitter
A34: Chairs | B34: Locate as per control plan | C34: Y | D34: Shopfitter
A35: Black unit for Cash Vac Capsules | B35: Install on wall near safe at the direction of the EPM | C35: Y | D35: Shopfitter
A36: Prepare Accessory Equipment for Checking Off in Offices | B36: Position equipment in Cashiers Office for checking | C36: Y | D36: Shopfitter
A37: Door Sign Kit as supplied | B37: Installed as per signage application guide Fixed to the door at 1250mm from finished floor level (to underside of the sign as per AS standard) | C37: Y | D37: Shopfitter
A38: TEAM PLANNING ROOM
A39: Equipment | B39: Fixing method | C39: Tick | D39: Work Done By
A40: Planning Table | B40: Locate as per control plan | C40: Y | D40: Shopfitter
...

Sheet Stockroom and Online
A1: =Bakery!A1 -> Store Name: Woolloongabba | B1: =Bakery!B1 -> RENEWAL & NEW STORE STORE - DAY WORKS AND NIGHT WORKS
A2: =Bakery!A2 -> Store Number: 2865 | B2: =Bakery!B2 -> FITOUT PERIOD AS PER PM'S & BUILDERS PROGRAM | D2: =Bakery!D2 -> V8
A3: =Bakery!A3 -> Plan Number Tendered On: Control Plan K 10/11/21 | B3: =Bakery!B3 -> START TBA COMPLETION DATE TBA - SUBJECT TO CHANGE | D3: =Bakery!D3 -> Updated
A4: =Bakery!A4 -> Date SOW Completed: 08/02/2022 | B4: =Bakery!B4 -> Shift P to enter a Tick | D4: =Bakery!D4 -> 44082
A5: STOCKROOM
A6: Equipment | B6: Fixing method | C6: Tick | D6: Work Done By
A7: Mailbox (Except QLD) | B7: Fixed to the wall in the outside dock area as per control plan. Fixed to the wall using plugs and screws. Fixed to the wall at a height of 1500mm above floor level. | D7: Shopfitter
A8: Workstation and Stool | B8: Locate as per control plan. Remove existing. | C8: Y | D8: Shopfitter
A9: Wall Bracket for Mop Rack and Brush Rack (Cleaning products) | B9: Locate as per control plan Fixed to the wall using plugs and screws and sealed to the wall using silicon Fixed to the wall at a height of 1500mm above floor level for both units | C9: Y | D9: Shopfitter
A10: Security Box for Temperature Gun | B10: Installed in the stockroom area near the storeman's workstation as EPM instruction Fixed to the wall using plugs and screws. Fixed to the wall at a height of 1600mm above floor level | C10: Y | D10: Shopfitter
A11: Equipment Reserve Fixture | B11: Install as per installation instructions and locate as per Control Plan SWL plaques to be installed every second upright | C11: Y | D11: Shopfitter
A12: Damaged Stock Fixture | B12: Install as per installation instructions Locate as per control plan SWL plaques to be installed every second upright | C12: Y | D12: Shopfitter
A13: First Aid Kit | B13: Fixed to the wall near the hand basin Fixed to the wall using plugs and screws and sealed to the wall using silicon Fixed to the wall at a height of 1270mm above floor level - installation locations not to be visible to customers | C13: Y | D13: Shopfitter
A14: "No Smoking" Sign | B14: Suspended throughout the Stockroom area as per Equipment Project Manager or affixed to a wall 2000mm from floor level | C14: Y | D14: Shopfitter
A15: Stockroom Checkpoints Signs | B15: Suspended or affixed to the wall in the stockroom area as per instruction from Equipment Project Manager at a height of 2000mm FFL (bottom of sign) | C15: Y | D15: Shopfitter
A16: Back Dock External Safety Signage (900x600). Back Dock Dangerous Goods Sign (600x300) | B16: Positioned 3 metres from finished ground level and as per external Signage plan. Fixed to external Wall using plugs and screws 3 metres from floor | C16: Y | D16: Shopfitter
A17: Insectocutor | B17: Suspended from the ceiling using stainless steel crimp wire Suspended from the ceiling at a height of minimum of 2400mm above floor level as shown on control plan | C17: Y | D17: Shopfitter
A18: Hazchem Sign (NSW/QLD only) | B18: Fixed in a prominent position at front and rear entries of the store (for Emergency Services benefit) on discussion and approval with Equipment Project Manager | C18: Y | D18: Shopfitter
A19: Staff Entry Signs | B19: Installed as per kit instructions Fixed to the door at 1500mm above floor level (to underside of the sign) | C19: Y | D19: Shopfitter
... A23: No Entry or Exit Signs | B23: Install as stores discretion | C23: Y | D23: Shopfitter
A24: CLEANERS ROOM
A25: Equipment | B25: Fixing method | C25: Tick | D25: Work Done By
A26: Cleaning Room Shelving | B26: Assembled as per the assembly instructions and located as per control plan. Adjust feet to ensure racking is level. SWL Plaque = 1 per room | C26: Y | D26: Shopfitter
A27: Mop & Broom Rack | B27: Fixed to the wall in the Cleaners Room in an accessible location as near to wash-up sink as possible. Fixed to the wall using plugs and screws. Fixed to the wall at a height of 1500mm above floor level | C27: Y | D27: Shopfitter
A28: Paper Towel Dispenser (Tork) | B28: Locate near the wash up sink Fixed to the wall using plugs and screws and sealed to the wall using silicon Locate in wash area - 1 in each toilet and 1 in kitchen near the sink | C28: Y | D28: Shopfitter
A29: ONLINE AREA
A30: Equipment | B30: Fixing method | C30: Tick | D30: Work Done By
A31: Racking | B31: Assembled as per the assembly instructions and located as per control plan. Adjust feet to ensure racking is level. SWL Plaque = 1 per room | C31: Y | D31: Shopfitter
A32: Bins | B32: Locate as per Control plan | C32: Y | D32: Shopfitter
A33: Benches and Trolleys | B33: Locate as per Control plan | C33: Y | D33: Shopfitter
A34: Fridges and Freezers | B34: Locate as per Control plan | C34: Y | D34: Shopfitter
A35: Mop & Broom Rack | B35: Fixed to the wall using plugs and screws. Fixed to the wall at a height of 1500mm above floor level | C35: Y | D35: Shopfitter
A36: First Aid Kit | B36: Locate as per control plan Fixed to the wall using plugs and screws and sealed to the wall using silicon Fixed to the wall at a height of 1270mm above floor level. Note - installation locations not to be visible to customers | C36: Y | D36: Shopfitter
A37: Insectocutors | B37: Wall mount a min of 1.7 to 2m from the base of the unit to floor level Avoid heat oil and sharp edges Use hardware provided in the kit for installation | C37: Y | D37: Shopfitter
A38: Paper Towel Dispenser (Tork) | B38: Locate near each hand wash basin Fixed to the wall using plugs and screws and sealed to the wall using silicon Fixed to the wall at a height of 940mm FFL (bottom) - store specific level may need to be to be confirmed by EPM pending any store specific obstructions. | C38: Y | D38: Shopfitter

Sheet Extra Tasks
A1: =Bakery!A1 -> Store Name: Woolloongabba | B1: =Bakery!B1 -> RENEWAL & NEW STORE STORE - DAY WORKS AND NIGHT WORKS
A2: =Bakery!A2 -> Store Number: 2865 | B2: =Bakery!B2 -> FITOUT PERIOD AS PER PM'S & BUILDERS PROGRAM | D2: =Bakery!D2 -> V8
A3: =Bakery!A3 -> Plan Number Tendered On: Control Plan K 10/11/21 | B3: =Bakery!B3 -> START TBA COMPLETION DATE TBA - SUBJECT TO CHANGE | D3: =Bakery!D3 -> Updated
A4: =Bakery!A4 -> Date SOW Completed: 08/02/2022 | B4: =Bakery!B4 -> Shift P to enter a Tick | D4: =Bakery!D4 -> 44082
A5: EXTRA SHOPFITTING TASKS
A6: Equipment | B6: Instructions | C6: Tick | D6: Work Done By
A7: Existing FME G-TRACK | B7: Allow to remove all existing, store and reinstall at the end of the program | D7: Shopfitter
A8: Workplace Health and Safety | B8: Comply with all WH&S Regulations, Woolworths Destination Zero requirements and directions of the Principal Contractor Maintain work area in a clean and tidy state by removing all rubbish into bins as it is generated | C8: Y | D8: Shopfitter
A9: Forklift/Scissor Lift | B9: Allow for forklift/scissor lift and licensed operator for unloading of delivery trucks and install for signage (Site Specific) | C9: Y | D9: Shopfitter
A10: Purchase Order Report | B10: Allow to check off the purchase order as per department delivery into the store. Supply EPM with updated copy as each department is finished off | C10: Y | D10: Shopfitter
