Workbook

Sheet Line_items_estimate
A1: Stage | B1: Task | C1: Description
A2: Planning | B2: Analysis of Input Sources and Schema Alignment | C2: Review input types (emails, PDFs, DOCX, HTML pages) and align to the unified Real Deals schema for structured extraction.
A3: Planning | B3: Evaluation of Parsing Options | C3: Assess extraction options using unstructured.io, PDF parsers, and web scrapers for consistent text and metadata capture.
A4: Planning | B4: RAG Pipeline Planning and Architecture | C4: Design retrieval-augmented extraction flow – embeddings, retrievers, schema-driven prompts, and output validation layer.
A5: Planning | B5: Analysis of Editorial Summary Requirements | C5: Study article structure and Real Deals writing tone for integration into two-stage summary generation.
A6: Planning | B6: Confidence Framework & Validation Rules | C6: Define confidence scoring logic and schema validation rules (Pydantic + Guardrails AI).
A7: Development | B7: Setup of Document Pre-processing Pipeline | C7: Build pipeline for text extraction, HTML/PDF parsing, cleaning, and markdown conversion.
A8: Development | B8: Embedding and Indexing for RAG | C8: Create vector embeddings of extracted content and store in FAISS/Chroma with metadata.
A9: Development | B9: Schema-Guided RAG Extraction Setup | C9: Implement retrieval + prompt-based extraction for all key data fields (Target, Sponsor, Sector, Value, etc.).
A10: Development | B10: Prompt Engineering and Schema Validation | C10: Develop structured prompts for each field and validate model outputs via Pydantic schema enforcement.
A11: Development | B11: Post-processing and Field Normalization | C11: Add normalization (currency, region, value range) and enrichment logic.
A12: Development | B12: Auto-Summary Template Creation (Stage 1) | C12: Implement auto-generated summary layer based on structured data placeholders.
... A16: Development | B16: End-to-End Testing & Handover | C16: Validate the full flow from input file → structured extraction → polished summary → CMS draft.

Sheet Consolidated Cost for Proposal
A1: Description | B1: Cost | C1: Comments
A2: Discovery, Analysis and Planning | B2: FOC | C2: Covered in POC | F2: Discovery, Analysis and Planning | J2: Solution Architect Split | K2: Margin Split AI | L2: Margin Split Scraping
A3: Solution Design and System Set up | B3: =SUM(G3:L3) -> 3474.9 | F3: Solution Design and System Set up | G3: 2200 | H3: 880 | J3: =0.1*G14 -> 150.2 | K3: =0.1*G18 -> 184.54 | L3: =0.1*H18 -> 60.16
A4: ScrapeX configuration – cXX sources | B4: =SUM(G4:L4) -> 2376 | F4: ScrapeX configuration – cXX sources | G4: - | H4: 2376
A5: AI/ML solution using KIAA framework - classifier, semantic de-duping, data mining | B5: =SUM(G5:L5) -> 9414.5 | F5: AI/ML solution using KIAA framework - classifier, semantic de-duping, data mining | G5: 7440 | J5: =0.5*G14 -> 751 | K5: =0.5*G18 -> 922.7 | L5: =0.5*H18 -> 300.8
A6: Solution Testing /QA (Tech) | B6: =SUM(G6:L6) -> 3878.6 | F6: Solution Testing /QA (Tech) | G6: 2500 | H6: 739 | J6: =0.1*G14 -> 150.2 | K6: =0.2*G18 -> 369.08 | L6: =0.2*H18 -> 120.32
A7: Data Transformation, Logging, Alerts, Reports and Delivery | B7: =SUM(G7:L7) -> 704 | F7: Data Transformation, Logging, Alerts, Reports and Delivery | H7: 704
A8: Solution Integration and Deployment | B8: =SUM(G8:L8) -> 4021.8 | F8: Solution Integration and Deployment | G8: 2880 | H8: 352 | J8: =0.2*G14 -> 300.4 | K8: =0.2*G18 -> 369.08 | L8: =0.2*H18 -> 120.32
A9: Documentation | B9: FOC | F9: Documentation | G9: FOC | H9: FOC
A10: Project Management | B10: FOC | F10: Project Management | G10: FOC | H10: FOC
A11: Total Solution Set Up / Configuration Costs | B11: =SUM(B2:B10) -> 23869.8 | F11: Buffer For Contingencies | G11: 1502 | H11: 505
F12: Infrastructure | G12: 430 | H12: 460
A13: Buffer For Contingencies | B13: =SUM(G11:H11) -> 2007 | G13: =SUM(G2:G12) -> 16952 | H13: =SUM(H2:H12) -> 6016
F14: Solution Architecture | G14: 1502
A15: Total Infra Costs | B15: =SUM(G12:H12) -> 890 | C15: Covered in Appendix IV | F15: Total | G15: =SUM(G3:G12,G14) -> 18454 | H15: =SUM(H3:H12) -> 6016
F16: Margin | G16: =G15*1.1 -> 20299.4 | H16: =H15*110% -> 6617.6
A17: Total Cost of Solution Customisation / Configuration | B17: =SUM(B11,B13,B15) -> 26766.8 | F17: Using our propieratory product ScrapeX we have saved XX% and by
F18: Savings using Merits accelerators | G18: =G16-G15 -> 1845.4 | H18: =H16-H15 -> 601.6
A23: Infrastructure + token costs ( * Approximate one time Set up cost for development but will be charged on actuals)
A24: Total Infra cost for initial phase | F24: =SUM(F25,F29) -> 430
A25: Virtual Machine(Ubuntu) - On-prem --Per Month cost - 1 A6 (4 Cores, 28 GB RAM) x 720 Hours (Pay as you go), Linux, (Pay as you go); 0 managed disks – S4; Inter Region transfer type, 5 GB outbound data transfer from UK South to East Asia | B25: 8 Cores, 16 GB RAM, 150 GB Temporary Storage 256 SSD | F25: 320
A26: Open AI - token cost
A27: Average Token cost per document (based on current pricing of openAI and the samples provided) - mainly GPT5 | F27: 0.11
A28: - 40 *25 days = 1000 | D28: 0 | F28: 1000
A29: Overall token cost for PoC | F29: =F28*F27 -> 110
A32: BAU - Ongoing Recurring Cost - monthly
A33: Average Token cost per document (based on current pricing of openAI and the samples provided) - Alternate between usage of 4o, o3 and o4-mini based on type of response | F33: =F27 -> 0.11
A34: Projected # of documents per month | F34: =F28 -> 1000
A35: Overall token costs per month | F35: =F34*F33 -> 110
A36: Support and Maintenance (Tech Resources) - 0.25 FTE ML engineer per month | B36: 30 | C36: ='[1]Rate Card'!$B$3 -> 30 | F36: =3500*0.25 -> 875
A37: Virtual Machine(Ubuntu) - On-prem | B37: 8 Cores, 16 GB RAM, 150 GB Temporary Storage 256 SSD | F37: 0
A38: Solution running cost
A39: BAU - Ongoing Recurring Cost - monthly | F39: =SUM(F37,F36,F35) -> 985

Sheet AIML_cost
A1: A. Customisation and Deployment of Solution - One off Cost
A2: AIML Solution - Document Classification & Information Retrieval | H2: Type | I2: Stage | L2: Week1 | M2: Week2 | N2: Week3 | O2: Week4 | P2: Week5 | Q2: Week6 | R2: Week7 | S2: Week8
A3: Description | B3: hrs_simple | C3: hrs_medium | D3: hrs | E3: Cost per hour | F3: total_cost | H3: Scraping | I3: End to End Scraping | L3: Week 1 | M3: Week 2 | N3: Week 3
A4: Planning - Customising AIML Framework for current requirement | D4: =SUM(D5:D9) -> 88 | F4: =SUM(F5:F9) -> 2200 | H4: AI/ML | I4: Planning - Customising AIML Framework for current requirement | J4: =D4/7 -> 12.571429 | K4: =J4/2/5 -> 1.2571429 | L4: Week 1 | M4: Week 2
A5: Analysis of Input Sources and Schema Alignment | C5: 16 | D5: 8 | E5: =lookup!$B$2 -> 25 | F5: =D5*$E5 -> 200 | I5: Development - AIML Framework | J5: =D14/7 -> 35.428571 | K5: =J5/2/5 -> 3.5428571 | N5: Week 3 | O5: Week 4 | P5: Week 5 | Q5: Week 6
A6: Assess extraction options using unstructured.io, PDF parsers, and web scrapers for consistent text and metadata capture. | C6: 24 | D6: 16 | E6: =lookup!$B$2 -> 25 | F6: =D6*$E6 -> 400 | I6: Integration Effort | J6: =D24/7 -> 13.714286 | K6: =J6/2/5 -> 1.3714286 | R6: Week 7 | S6: Week 8
A7: Design retrieval-augmented extraction flow – embeddings, retrievers, schema-driven prompts, and output validation layer. | C7: 16 | D7: 32 | E7: =lookup!$B$2 -> 25 | F7: =D7*$E7 -> 800
A8: Analysis of Editorial Summary Requirements - Study article structure and Real Deals writing tone for integration into two-stage summary generation. | C8: 24 | D8: 24 | E8: =lookup!$B$2 -> 25 | F8: =D8*$E8 -> 600
A9: Define confidence scoring logic and schema validation rules (Pydantic + Guardrails AI). | C9: 24 | D9: 8 | E9: =lookup!$B$2 -> 25 | F9: =D9*$E9 -> 200
A10: Project Mgmt cost - Planning | D10: =SUM(D11:D13) -> 0 | F10: =SUM(F11:F13) -> 0
A11: Solution Architect Effort | D11: =ROUNDUP(SUM($D$5:$D$9)*lookup!B7,0) -> 0 | E11: 40 | F11: =D11*$E11 -> 0
A12: PM Effort | D12: =ROUNDUP(SUM($D$5:$D$9)*lookup!B8,0) -> 0 | E12: =lookup!$B$2 -> 25 | F12: =D12*$E12 -> 0
A13: BA Effort | D13: =ROUNDUP(SUM($D$5:$D$9)*lookup!B13,0) -> 0 | E13: =lookup!$B$2 -> 25 | F13: =D13*$E13 -> 0
A14: Development - AIML Framework | D14: =SUM(D15:D23) -> 248 | F14: =SUM(F15:F23) -> 7440
A15: Setup of Document Pre-processing Pipeline - Build pipeline for text extraction, HTML/PDF parsing, cleaning, and markdown conversion. | D15: 16 | E15: =lookup!$C$2 -> 30 | F15: =D15*$E15 -> 480
A16: Embedding and Indexing for RAG | D16: 24 | E16: =lookup!$C$2 -> 30 | F16: =D16*$E16 -> 720
A17: Schema-Guided RAG Extraction Setup - Implement retrieval + prompt-based extraction for all key data fields (Target, Sponsor, Sector, Value, etc.). | D17: 56 | E17: =lookup!$C$2 -> 30 | F17: =D17*$E17 -> 1680
A18: Prompt Engineering and Schema Validation - Develop structured prompts for each field and validate model outputs via Pydantic schema enforcement. | D18: 32 | E18: =lookup!$C$2 -> 30 | F18: =D18*$E18 -> 960
A19: Post-processing and Field Normalization - Add normalization (currency, region, value range) and enrichment logic. | D19: 24 | E19: =lookup!$C$2 -> 30 | F19: =D19*$E19 -> 720
A20: Auto-Summary Template Creation (Stage 1) - based on structured data placeholders. | D20: 24 | E20: =lookup!$C$2 -> 30 | F20: =D20*$E20 -> 720
A21: Editorial Refinement Model (Stage 2) - Develop AI-based editorial polish module to rewrite Stage 1 outputs in Real Deals tone. | D21: 24 | E21: =lookup!$C$2 -> 30 | F21: =D21*$E21 -> 720 | I21: Discovery, Analysis and Planning
A22: Map structured outputs and summaries to Azure SQL + ExpressionEngine CMS via API connector. | D22: 24 | E22: =lookup!$C$2 -> 30 | F22: =D22*$E22 -> 720 | I22: Solution Design and System Set up | J22: 2200 | K22: 880
A23: Evaluation and Fine-tuning of Extraction Accuracy | D23: 24 | E23: =lookup!$C$2 -> 30 | F23: =D23*$E23 -> 720 | I23: ScrapeX configuration – cXX sources | J23: - | K23: 2464
A24: Integration Effort | D24: =SUM(D25:D26) -> 96 | F24: =SUM(F25:F26) -> 2880 | I24: AI/ML solution using KIAA framework - classifier, semantic de-duping, data mining | J24: 7440 | K24: -
A25: Azure SQL Database (structured storage for extracted fields) ExpressionEngine CMS (publishing layer for editorial summaries) | D25: 64 | E25: =lookup!$C$2 -> 30 | F25: =D25*$E25 -> 1920 | I25: Solution Testing /QA (Tech) | J25: 2500 | K25: 756
A26: Integration testing | D26: 32 | E26: =lookup!$C$2 -> 30 | F26: =D26*$E26 -> 960 | I26: Data Transformation, Logging, Alerts, Reports and Delivery | K26: 440
A27: Documentation - AIML Framework | D27: =SUM(D28:D30) -> 0 | F27: =SUM(F28:F30) -> 0 | I27: Automated Validation Checks
A28: Code Standardization | D28: 0 | E28: =lookup!$B$2 -> 25 | F28: =D28*$E28 -> 0 | I28: Solution Integration and Deployment | J28: 2880 | K28: 352
A29: Code Documentation | D29: 0 | E29: =lookup!$B$2 -> 25 | F29: =D29*$E29 -> 0 | I29: Documentation | J29: 600 | K29: 0
A30: Documentation - user manual | D30: 0 | E30: =lookup!$B$2 -> 25 | F30: =D30*$E30 -> 0 | I30: Project Management | J30: 3124 | K30: 0
A31: Testing - AIML Framework | D31: =SUM(D32:D33) -> 100 | F31: =SUM(F32:F33) -> 2500 | I31: Buffer For Contingencies | J31: 1562 | K31: 490
A32: Unit testing | B32: 14 | C32: 24 | D32: =ROUNDUP(0.2*D14,0) -> 50 | E32: =lookup!$D$2 -> 25 | F32: =D32*$E32 -> 1250 | I32: Infrastructure | J32: 430 | K32: 460
A33: Data quality | B33: 14 | C33: 24 | D33: =ROUNDUP(0.2*D14,0) -> 50 | E33: =lookup!$D$2 -> 25 | F33: =D33*$E33 -> 1250 | J33: =SUM(J21:J32) -> 20736 | K33: =SUM(K21:K32) -> 5842
A34: Total Production Man Hours | D34: =SUM(D4,D14,D24,D27,D31) -> 532
A35: Total Cost | F35: =SUM(F4,F14,F24,F27,F31) -> 15020
A36: =lookup!H2&" Effort @ "&lookup!I2 -> Solution Architect Effort @ 0.1 | D36: =ROUNDUP(D14*lookup!C7,0) -> 0 | E36: 0 | F36: =F$35*lookup!I2 -> 1502
A37: =lookup!H3&" Effort @ "&lookup!I3 -> PM Effort @ 0 | D37: =ROUNDUP(D14*lookup!C8,0) -> 0 | E37: 0 | F37: =F$35*lookup!I3 -> 0 | I37: 532 | K37: 4 sources
A38: =lookup!H4&" Effort @ "&lookup!I4 -> BA Effort @ 0 | D38: =ROUNDUP(SUM($D$5:$D$9)*lookup!C13,0) -> 0 | E38: 0 | F38: =F$35*lookup!I4 -> 0 | G38: 5 | I38: 8
A39: =lookup!H5&" @ "&lookup!I5 -> Contingency @ 0.1 | D39: =ROUNDUP(SUM(D34:D38)*0.2,0) -> 107 | E39: 22 | F39: =F$35*lookup!I5 -> 1502 | I39: =I37/I38 -> 66.5
A40: Grand Total - One time setup Cost | F40: =SUM(F4,F10,F14,F24,F27,F31,F36:F39) -> 18024 | I40: =I39/21 -> 3.1666667
...

Sheet DataHarvesting_cost
A1: Robust Solution Development for Deals Extraction
A3: I. Design, Development and Deployment of Solution - One off Cost
A4: S.No | B4: Project Task / Activity Description | C4: Cost per hour | D4: Effort in Hours | E4: Total Cost
A6: 1 | B6: Planning, Design and System Set up | C6: =lookup!$C$19 -> 22 | D6: =SUM(D7:D9) -> 40 | E6: =C6*D6 -> 880
A7: 1.2 | B7: Solution Approach (System Architecture and Database Design) | D7: 24
A8: 1.3 | B8: Infrastructure Setup | D8: 16
A10: 2 | B10: Scraper Development/Configuration | C10: =lookup!$C$19 -> 22 | D10: =SUM(D11:D13) -> 108 | E10: =C10*D10 -> 2376
A11: 2.1 | B11: 40 Sources Scraper development | D11: ='Sources Details'!F5 -> 72
A12: 2.2 | B12: Data collection from email subscriptions | D12: ='Sources Details'!E25 -> 28
A13: 2.3 | B13: Open Search(Google OpenSearch limited to first 10 pages to identify relevant base articles or leads) | D13: 8
A14: 2.4 | B14: Organisation Details Extraction(Trade or Registered company name, Turnover, Revenue (Profit), Sectors, Region (deal level).) | D14: 16
A15: 3 | B15: Data Transformation, Logging, Alerts, Reports and Delivery | C15: =lookup!$C$19 -> 22 | D15: =SUM(D16:D19) -> 32 | E15: =C15*D15 -> 704
A16: 3.1 | B16: Download and Upload processed files(Raw responses will be stored in Blob storage) | D16: 12
A17: 3.2 | B17: Content DeDuping | D17: 8
A18: 3.4 | B18: Logging | D18: 12
A20: 4 | B20: Data Quality & Validation | C20: =lookup!$C$19 -> 22 | D20: 12 | E20: =C20*D20 -> 264
A21: 4.1 | B21: Automated Checks - Data Validation
A22: 5 | B22: UAT Issue Fixes | C22: =lookup!$C$19 -> 22 | D22: =D10*0.2 -> 21.6 | E22: =C22*D22 -> 475.2
A23: 6 | B23: Integration and Deployment | C23: =lookup!$C$19 -> 22 | D23: 16 | E23: =C23*D23 -> 352
A24: 7 | B24: Documentation | C24: =lookup!$C$19 -> 22 | D24: 0 | E24: =C24*D24 -> 0
A25: 8 | B25: Project Management | C25: =lookup!$C$19 -> 22 | D25: 0 | E25: =C25*D25 -> 0
A26: 8.1 | B26: Project Management Charges(PM and BAs)
B27: Total Estimated Hours | C27: =lookup!$C$19 -> 22 | D27: =SUM(D6,D10,D15,D20,D22,D23,D24,D25) -> 229.6 | E27: =C27*D27 -> 5051.2
B28: Buffer for Contingencies(10%) | C28: =lookup!$C$19 -> 22 | D28: =D27*0.1 -> 22.96 | E28: =C28*D28 -> 505.12
B29: Infrastructure Charges During Set Up | E29: =Infrastructure_Details!D14 -> 460
B30: Total Set Up Costs | D30: =SUM(D27:D28) -> 252.56 | E30: =SUM(E27:E29) -> 6016.32
A33: * Note :Costs will be impacted if scraper schedule changes to daily/ monthly or any other custom schedule
A36: BAU - Deals Extraction(*Daily)
A37: Infrastructure Details | K37: Proxy Services
A38: S.No | B38: Infrastructire Charges During POC | C38: FTE Count | D38: Cost(Azure and third party services) | G38: 0.1 | H38: 350 | I38: 535 | K38: Virtual Machine(Ubuntu)
A39: 1 | B39: Tech Support | C39: 0.15 | D39: =C39*3000 -> 450 | G39: 0.25 | H39: 875 | I39: 110 | K39: DataBase
A40: S.No | B40: Infrastructire Charges During POC | D40: Cost(Azure and third party services) | K40: Storage
A41: 1 | B41: Proxy Services | C41: Region specific proxies | D41: 60 | E41: Will be billed on actuals | K41: Backup
A42: 2 | B42: Virtual Machine(Ubuntu) | C42: AMD EPYC 9554 - CPU-4x-16GB | D42: 100 | E42: Will be billed on actuals | K42: Serper(Open Search)
A43: 3 | B43: DataBase | C43: D Series, 4 vCore, £0.2955/hour | D43: 275 | E43: Will be billed on actuals | K43: Virtual Machine(Ubuntu) - AMD EPYC 9554 - CPU-8x-32GB
A44: 4 | B44: Storage | D44: 20 | E44: Will be billed on actuals | K44: Open AI - token cost
A45: 5 | B45: Backup | D45: 20 | E45: Will be billed on actuals
A46: 6 | B46: Serper(Open Search) | D46: 60 | E46: Subscription cost
A48: Total Monthly Cost | D48: =SUM(D39:D46) -> 985

Sheet Infrastructure_Details
A1: Robust Solution Development for Finding Land Purchase deals(Datacenters)
A2: Infrastructure Details
A3: S.No | B3: Infrastructire Charges During POC | D3: Cost(Azure and third party services)
A4: 1 | B4: Proxy Services | C4: Region specific proxies | D4: 60 | E4: Will be billed on actuals
A5: 2 | B5: Virtual Machine(Ubuntu) | C5: AMD EPYC 9554 - CPU-4x-16GB | D5: 100 | E5: Will be billed on actuals
A6: 3 | B6: DataBase | C6: D Series, 4 vCore, £0.2955/hour | D6: 200 | E6: Will be billed on actuals
A7: 4 | B7: Storage | D7: 20 | E7: Will be billed on actuals
A8: 5 | B8: Backup | D8: 20 | E8: Will be billed on actuals
A9: 6 | B9: Serper(Open Search) | D9: 60 | E9: Subscription cost
B11: AI/ML Infra
A12: 1 | B12: GPU Machine
A13: 2 | B13: Open AI Key
A14: Total Monthly Cost | D14: =SUM(D4:D13) -> 460

Sheet Resource Loading Sheet
A1: Type | B1: Stage | C1: Days | D1: Weeks | E1: Week1 | F1: Week2 | G1: Week3 | H1: Week4 | I1: Week5 | J1: Week6 | K1: Week7 | L1: Week8
A2: Scraping | B2: End to End Scraping | E2: Week 1 | F2: Week 2 | G2: Week 3
A3: AI/ML | B3: Planning - Customising AIML Framework for current requirement | C3: 12.571429 | D3: 1.2571429 | E3: Week 1 | F3: Week 2
B4: Development - AIML Framework | C4: 35.428571 | D4: 3.5428571 | G4: Week 3 | H4: Week 4 | I4: Week 5 | J4: Week 6
B5: Integration Effort | C5: 13.714286 | D5: 1.3714286 | K5: Week 7 | L5: Week 8

Sheet AIML_workflow
A1: Web & Document Collection
A2: Automatically capture deal announcements, press releases, and updates from company websites, investor pages, and emails.
A3: Support multiple formats such as .eml, .pdf, .docx, and .html.
A4: Record key source metadata (URL, publication date, document type) for tracking and auditability.
A5: Content Parsing & Structuring
A6: Extract readable text from varied file types using automated parsing tools.
A7: Clean and organize content to remove non-informative sections like disclaimers, footers, and hyperlinks.
A8: Segment text into logical sections (e.g., company background, deal rationale, financials) to improve AI accuracy.
A9: AI-Powered Data Extraction
A10: Apply a Retrieval-Augmented Generation (RAG) pipeline aligned to a pre-defined schema.
A11: Automatically identify and extract key entities (e.g., Target, Sponsor, Fund, Seller) and financial data (Deal Value, Turnover, Profit).
A12: Generate structured JSON output with confidence scores for each extracted field.
... A23: Maintain an audit log of processed documents, extracted data, and system confidence levels.

Sheet Sources Details
A1: Total Sources(Assumption) | B1: 40
A2: Category | B2: Approx. % of Sources | C2: Approx. Count (out of 2000) | D2: Scraping Approach | E2: Hours Required(for each website) | F2: Total Hours Required
A3: Common Framework (Press releases, News Rooms, Third party news sources and org press and news releases) | B3: 0.6 | C3: =B1*B3 -> 24 | D3: Generic crawler framework (Scrapy + Playwright + article/PDF/text extractor + NLP for facts) | E3: 1 | F3: =C3*E3 -> 24
A4: Custom Scrapers | B4: 0.4 | C4: =B4*B1 -> 16 | D4: Site-specific scrapers, form-handling, OCR for PDFs, multilingual pipelines OCR (Donut/Tesseract) + translation dictionaries/models | E4: 3 | F4: =C4*E4 -> 48
A5: Total | F5: =SUM(F3:F4) -> 72 | H5: =F5/40 -> 1.8
A10: Gmail Email Reading & Attachment Download(for Free Official API)
A11: Task Description | B11: Analysis (In hours) | C11: Development (In hours) | D11: Testing (In hours) | E11: Total Efforts (In Hours)
A12: Requirement understanding & API feasibility for Gmail | B12: 2 | C12: 0 | D12: 0 | E12: 2
A13: Implement Gmail API integration to read emails & download attachments | B13: 2 | C13: 14 | D13: 4 | E13: 20
A14: Logging, reporting, and storage setup for downloaded attachments | B14: 1 | C14: 6 | D14: 2 | E14: 9
A15: End-to-end testing & documentation | B15: 1 | C15: 3 | D15: 2 | E15: 6
A16: Total | B16: 6 | C16: 23 | D16: 8 | E16: 37
A19: Outlook (Microsoft Graph) Email Reading & Attachment Download(for Free Official API)
A20: Task Description | B20: Analysis (In hours) | C20: Development (In hours) | D20: Testing (In hours) | E20: Total Efforts (In Hours)
A21: Requirement understanding & API feasibility for Outlook | B21: 2 | C21: 0 | D21: 0 | E21: =SUM(B21:D21) -> 2
A22: Implement Outlook (Microsoft Graph API) integration to read emails & download attachments | B22: 2 | C22: 12 | D22: 2 | E22: =SUM(B22:D22) -> 16
A23: Logging, reporting, and storage setup for downloaded attachments | B23: 1 | C23: 4 | D23: 1 | E23: =SUM(B23:D23) -> 6
A24: End-to-end testing & documentation | B24: 1 | C24: 2 | D24: 1 | E24: =SUM(B24:D24) -> 4
A25: Total | B25: =SUM(B21:B24) -> 6 | C25: =SUM(C21:C24) -> 18 | D25: =SUM(D21:D24) -> 4 | E25: =SUM(E21:E24) -> 28
A29: Data ingested into CMS via API(endpoints, authentication, payload, error handling)
A30: Task Description | B30: Analysis (In hours) | C30: Development (In hours) | D30: Testing (In hours) | E30: Total Efforts (In Hours)
A31: Requirement understanding & API documentation review | B31: 2 | C31: 0 | D31: 0 | E31: =SUM(B31:D31) -> 2
A32: Data mapping & validation logic | B32: 3 | C32: 12 | D32: 3 | E32: =SUM(B32:D32) -> 18
A33: CMS API integration & batch processing | B33: 2 | C33: 4 | D33: 2 | E33: =SUM(B33:D33) -> 8
A34: Error handling & retry mechanism | B34: 1 | C34: 2 | D34: 1 | E34: =SUM(B34:D34) -> 4
A35: Deployment setup (Docker & CI/CD) | B35: 2 | C35: 8 | D35: 2 | E35: =SUM(B35:D35) -> 12
A36: End-to-end testing & documentation | B36: 2 | C36: 4 | D36: 2 | E36: =SUM(B36:D36) -> 8
A37: TOTAL | B37: =SUM(B31:B36) -> 12 | C37: =SUM(C31:C36) -> 30 | D37: =SUM(D31:D36) -> 10 | E37: =SUM(E31:E36) -> 52

Sheet Call - Queries and Answers
A1: Section / Topic | B1: Discussion Summary | C1: Clarifications / Actions | D1: Next Steps / Notes
A2: Missing Seller Fields | B2: Some Seller fields in sample data are blank. | C2: Seller Name (Free Text) captured only if Seller is a financial sponsor (from Organization table). Not captured for private companies. If Seller + Parent Company exist, Seller Type and Organization always covered. | D2: Document in data validation logic how missing Seller information should be handled.
A3: External Validation (Company / Deal Data) | B3: Discussion on validating data with external corporate data sources. | C3: Additional fields to include: Organization information, Turnover, Revenue (Profit), Sectors, Region (deal level).
A4: Data Enrichment via Open Web | B4: Question on using open web (Google Search) to fill missing structured fields. | C4: Permitted practice – team uses Google Search to fill in missing fields where applicable. | D4: Define a confidence scoring or tagging mechanism for data enriched via open web.
A5: Deal Coverage Scope | B5: Clarified if deals are region or domain-specific. | C5: All deals covered – no filters by region or sector. Region-specific sources available for France and Spain etc | D5: Ensure schema and pipeline support multilingual and region-specific formats.
A6: Financial Data Sources | B6: Financial / filing data sources by country. | C6: For UK: Companies House used as the main source. | D6: Identify equivalent regulatory data sources for other regions (EU, US, APAC).
A7: Regional and Sectoral Prioritization | B7: Discussion on granularity level for geography. | C7: Region → Country → Sub-region (State / County). Team will share this mapping. | D7: Await region & sub-region mapping document for integration into metadata standards.
A8: CMS Ingestion Process | B8: Understanding current ingestion workflow. | C8: Data ingested into CMS via API (no CSV/manual upload). Requires structured payload as per schema. | D8: Obtain API documentation (endpoints, authentication, payload, error handling).

Sheet consolidated_sheet
A1: Scraping Solution Development
A3: I. Design, Development and Deployment of Solution - One off Cost
A4: I.1 | B4: Project Task / Activity Description | C4: Cost per hour | D4: Effort in Hours | E4: Total Cost
A5: I.1.a | B5: Source Configuration | C5: 22 | D5: 174 | E5: =C5*D5 -> 3828
A6: I.1.b | B6: Data Transformation(Cleansing and Formatting) | C6: 22 | D6: 8 | E6: =C6*D6 -> 176
A7: I.1.c | B7: Downloader Script | C7: 22 | D7: 24 | E7: =C7*D7 -> 528
A8: I.1.d | B8: System and DB Design | C8: 22 | D8: 8 | E8: =C8*D8 -> 176
A9: I.1.e | B9: UAT Support | C9: 22 | D9: 24 | E9: =C9*D9 -> 528
A10: I.1.f | B10: Integration and Deployment | C10: 22 | D10: 32 | E10: =C10*D10 -> 704
A11: I.2 | B11: Project Management
A12: I.2.a | B12: Project Management Charges(PM and BAs) | C12: 30 | D12: =SUM(D5:D10)*0.25 -> 67.5 | E12: =C12*D12 -> 2025
A13: I.2.b | B13: Documentation | C13: 12 | D13: 8 | E13: =C13*D13 -> 96
A14: I.3 | B14: Infrastructire Charges During Set Up
A15: 1.3.a | B15: To be paid on actuals | D15: Approximately | E15: =[2]Scraper_Estimation!C83 -> 640
B16: Total Estimated Hours | D16: =SUM(D5:D13) -> 345.5 | E16: =SUM(E5:E15) -> 8701
B17: Buffer for Contingencies | C17: 22 | D17: =D16*10% -> 34.55 | E17: =C17*D17 -> 760.1
B18: Total Set Up Costs | E18: =SUM(E16:E17) -> 9461.1
A20: II. BAU - Ongoing Recurring Cost (Scrpaers Run Weekly *) - Monthly Charges
A21: II.1 | B21: Support and Maintenance Resources | D21: FTE(Quantity) | E21: Cost
A22: II.1.a | B22: Support and Maintenance (Tech Resources) | D22: 0.25 | E22: =D22*3500 -> 875
A23: I.2 | B23: Infrastructire Charges During BAU
A24: II.2.a | B24: Proxies for Scraping(15 Ips) | D24: Approximately | E24: 95
A25: II.2.b | B25: Virtual Machine(Ubuntu) | D25: Approximately | E25: 200
A26: II.2.c | B26: MySQL | D26: Approximately | E26: 275
A27: II.2.d | B27: Document Storage | D27: Approximately | E27: 60
A28: II.2.e | B28: Back-up | D28: Approximately | E28: 10
B29: Total Monthly Cost | E29: =SUM(E22:E28) -> 1515
A31: * Note :Costs will be impacted if scraper schedule changes to daily/ monthly or any other custom schedule
A35: ML Solution Development
A37: I. Design, Development and Deployment of Solution - One off Cost
A38: I.1 | B38: Project Task / Activity Description | C38: Cost per hour | D38: Effort in Hours | E38: Total Cost
A39: I.1.a | B39: Planning - AIML Framework | D39: =VLOOKUP($B39,AIML_cost!$A:$F,4,0) -> #N/A | E39: =VLOOKUP($B39,AIML_cost!$A:$F,6,0) -> #N/A
A40: I.1.b | B40: Development - AIML Framework | D40: =VLOOKUP($B40,AIML_cost!$A:$F,4,0) -> 248 | E40: =VLOOKUP($B40,AIML_cost!$A:$F,6,0) -> 7440
A41: I.1.c | B41: Integration Effort | D41: =VLOOKUP($B41,AIML_cost!$A:$F,4,0) -> 96 | E41: =VLOOKUP($B41,AIML_cost!$A:$F,6,0) -> 2880
A42: I.1.d | B42: Documentation - AIML Framework | D42: =VLOOKUP($B42,AIML_cost!$A:$F,4,0) -> 0 | E42: =VLOOKUP($B42,AIML_cost!$A:$F,6,0) -> 0
A43: I.1.e | B43: Testing - AIML Framework | D43: =VLOOKUP($B43,AIML_cost!$A:$F,4,0) -> 100 | E43: =VLOOKUP($B43,AIML_cost!$A:$F,6,0) -> 2500
A44: I.2 | B44: Project Management
A45: I.2.a | B45: Solution Architect Effort | D45: =AIML_cost!D11+AIML_cost!D36 -> 0 | E45: =AIML_cost!F11+AIML_cost!F36 -> 1502
A46: I.2.b | B46: PM Effort | D46: =AIML_cost!D12+AIML_cost!D37 -> 0 | E46: =AIML_cost!F12+AIML_cost!F37 -> 0
B47: Contingency @ 10% | D47: =VLOOKUP($B47,AIML_cost!$A:$F,4,0) -> #N/A | E47: =VLOOKUP($B47,AIML_cost!$A:$F,6,0) -> #N/A
...

Sheet lookup
B1: plan | C1: dev | D1: testing | H1: Role | I1: Effort%
A2: Labor cost | B2: 25 | C2: 30 | D2: 25 | H2: Solution Architect | I2: 0.1
A3: UI labor cost | C3: 22 | H3: PM | I3: 0
H4: BA | I4: 0
H5: Contingency | I5: 0.1
B6: plan | C6: dev
A7: Solution Architect Effort | B7: 0 | C7: 0
A8: PM Effort | B8: 0 | C8: 0
A9: Dev Unit Testing | B9: 0.2 | C9: 0.2
A10: QA Testing | B10: 0.25 | C10: 0.25
A11: Integration Testing | B11: 0.2 | C11: 0.2
A13: BA Effort | B13: 0 | C13: 0
A17: Scraping Labor cost
B18: plan | C18: dev | D18: testing | E18: w
A19: Labor cost | B19: 22 | C19: 22 | D19: 22 | E19: 30

Sheet unit_cost
A1: One time cost | B1: =AIML_cost!F40 -> 18024
A2: infra | B2: =AIML_cost!F43 -> 280
A3: BAU per month | B3: =AIML_cost!F58 -> 1030
A4: BAU per year | B4: =B3*12 -> 12360
A5: Total cost | B5: =SUM(B1,B2,B4) -> 30664
A6: # of entries per year | B6: =40*25*12 -> 12000
A7: cost per document | B7: =(B1+B2)/B6 -> 1.5253333

Sheet Resource Loading
H3: Sprint-1 | R3: Sprint-2 | AB3: Sprint-3 | AL3: Hardening | AQ3: Sprint-4 | BA3: Sprint-5 | BK3: Sprint-6 | BU3: UAT & Deployment | BZ3: Warranty & Support
B4: Streams | C4: Roles | D4: Count | E4: Planned Capacity (hrs) | F4: No of Productive days | G4: No. of weeks | H4: Week-1 | M4: Week-2 | R4: Week-3 | W4: Week-4 | AB4: Week-5 | AG4: Week-6 | AL4: Week-7 | AQ4: Week-8 | AV4: Week-9 | BA4: Week-10 | BF4: Week-11 | BK4: Week-12 | BP4: Week-13 | BU4: Week-14 | BZ4: Week-15 | CE4: Week-16
B5: Scraper | C5: Python resources - Pipeline & Transformation | D5: 1
C6: Lead Python resources (Source config) | D6: 1
C7: Sr.Python resources (Source config) | D7: 1
C8: Python resources (Source config) | D8: 1
B9: AI/ML | C9: DA | D9: 1
C10: AI/ML Consultant | D10: 1
C11: Sr. AI/ML Dev | D11: 1 | E11: =SUM(AIML_cost!$D$4,AIML_cost!$D$14,AIML_cost!$D$24)/2 -> 216 | F11: =E11/7 -> 30.857143 | G11: =F11/5 -> 6.1714286
C12: AI/ML Dev | D12: 1 | E12: =SUM(AIML_cost!$D$4,AIML_cost!$D$14,AIML_cost!$D$24)/2 -> 216 | F12: =E12/7 -> 30.857143 | G12: =F12/5 -> 6.1714286
B13: Proj Mgmt | C13: PM | D13: 1
C14: Scraping Lead | D14: 0.5
C15: AI/ML Lead | D15: 0.5
C16: BA | D16: 1
B17: Total
C18: Buffer
B19: Total | D19: =SUM(D5:D16) -> 11
H22: Type | I22: Stage | L22: Week1 | M22: Week2 | N22: Week3 | O22: Week4 | P22: Week5 | Q22: Week6 | R22: Week7 | S22: Week8
B23: SL No | C23: Modules | D23: Effort (hrs) | E23: Cost | F23: Remarks | H23: Scraping | I23: End to End Scraping | L23: Week 1 | M23: Week 2 | N23: Week 3
C24: Scrapping Soution | D24: =[1]Scraping!F22 -> 1578 | E24: =[1]Scraping!H22 -> 53500 | H24: AI/ML | I24: Planning - Customising AIML Framework for current requirement | J24: 12.571429 | K24: 1.2571429 | L24: Week 1 | M24: Week 2
C25: AI/ML Solution | D25: =[1]pricing_estimate_AIML!B70 -> 807.1 | E25: =[1]pricing_estimate_AIML!D52 -> 23509.5 | I25: Development - AIML Framework | J25: 35.428571 | K25: 3.5428571 | N25: Week 3 | O25: Week 4 | P25: Week 5 | Q25: Week 6
C26: Web App Solution | D26: ='[1]Web Application'!B46 -> 807.48 | E26: ='[1]Web Application'!D46 -> 21214.12 | I26: Integration Effort | J26: 13.714286 | K26: 1.3714286 | R26: Week 7 | S26: Week 8
C27: Total Build Effort | D27: =SUM(D24:D26) -> 3192.58 | E27: =SUM(E24:E26) -> 98223.62
C28: PM | D28: =D27*0.25 -> 798.145 | E28: =D28*'[1]Rate Card'!B5 -> 23944.35 | F28: 25% of Build effort
C29: BA | D29: =D27*0.2 -> 638.516 | E29: =D29*'[1]Rate Card'!B4 -> 12770.32 | F29: 20 % of Build effort ? - To be discussed
C30: Documentation ? | D30: 0 | E30: 0 | F30: Free of Cost
C31: Client training ? | D31: 40 | E31: =D31*'[1]Rate Card'!F7 -> 800
C32: Overall Buffer | D32: =D27*0.1 -> 319.258 | E32: =D32*'[1]Rate Card'!F8 -> 7342.934 | F32: 10% of Build effort - To be discussed
C33: Scrapping infra cost | E33: =[1]Scraping!F31 -> 1190 | F33: Is this PCM cost? or for the entire build / set up duration?
C34: Overall Set Up Costs | E34: =SUM(E28:E33)+E27 -> 144271.22
C35: Application Support and Maintaince | E35: =[1]Scraping!F45 *24 -> 196560 | F35: Cost calculated for 2 year : Monthly cost - £8,184
C36: Misc ??
C37: Total Solution Effort | D37: =SUM(D27:D32) -> 4988.499 | E37: =SUM(E24:E35) -> 583326.07
C39: Productive days | D39: =D37/D45 -> 712.64271
C40: No of days per resource on average | D40: =620/10 -> 62
C41: No of weeks | D41: =62/5 -> 12.4
C42: No of sprint | D42: =D41/2 -> 6.2
C44: Assumptions
C45: Productive hours | D45: 7
C46: Days/week | D46: 5
